Workbook
Name _1.: April!$C$3:$I$41
Name _1.S: April!$C$41:$I$41
Name _10.: April!$L$3:$R$41
Name _10.s: April!$M$41:$R$41
Name _11.: April!$M$3:$S$41
Name _11.s: April!$N$41:$S$41
Name _12.: April!$N$3:$T$41
Name _12.s: April!$O$41:$T$41
Name _13.: April!$O$3:$U$41
Name _13.s: April!$P$41:$U$41
Name _14.: April!$P$3:$V$41
Name _14.s: April!$Q$41:$V$41
Name _15.: April!$Q$3:$W$41
Name _15.s: April!$R$41:$W$41
Name _16.: April!$R$3:$X$41
Name _16.s: April!$S$41:$X$41
Name _17.: April!$S$3:$Y$41
Name _17.s: April!$T$41:$Y$41
Name _18.: April!$T$3:$Z$41
Name _18.s: April!$U$41:$Z$41
Name _19.: April!$U$3:$AA$41
Name _19.s: April!$V$41:$AA$41
Name _2.: April!$D$3:$J$41
Name _2.s: April!$E$41:$J$41
Name _20.: April!$V$3:$AB$41
Name _20.s: April!$W$41:$AB$41
Name _21.: April!$W$3:$AC$41
Name _21.s: April!$X$41:$AC$41
Name _22.: April!$X$3:$AD$41
Name _22.s: April!$Y$41:$AD$41
Name _23.: April!$Y$3:$AE$41
Name _23.s: April!$Z$41:$AE$41
Name _24.: April!$Z$3:$AF$41
Name _24.s: April!$AA$41:$AF$41
Name _25.a: April!$AA$3:$AF$41
Name _25.b: April!$C$3:$C$41
Name _25.s: [1]April!$AB$41:$AF$41,[1]April!$C$41:$C$41
Name _25.s: April!$AB$41:$AF$41,April!$C$41:$C$41
Name _26.a: April!$AB$3:$AF$41
Name _26.b: April!$C$3:$D$41
Name _26.s: [1]April!$C$41:$D$41,[1]April!$AC$41:$AF$41
Name _26.s: April!$C$41:$D$41,April!$AC$41:$AF$41
Name _27.a: April!$AC$3:$AF$41
Name _27.b: April!$C$3:$E$41
Name _27.s: [1]April!$AD$41:$AF$41,[1]April!$C$41:$E$41
Name _27.s: April!$AD$41:$AF$41,April!$C$41:$E$41
Name _28.a: April!$AD$3:$AF$41
Name _28.b: April!$C$3:$F$41
Name _28.s: [1]April!$AE$41:$AF$41,[1]April!$C$41:$F$41
Name _28.s: April!$AE$41:$AF$41,April!$C$41:$F$41
Name _29.a: April!$AE$3:$AF$41
Name _29.b: April!$C$3:$G$41
Name _29.s: [1]April!$AF$41:$AF$41,[1]April!$C$41:$G$41
Name _29.s: April!$AF$41:$AF$41,April!$C$41:$G$41
Name _3.: April!$E$3:$K$41
Name _3.s: April!$F$41:$K$41
Name _30.a: April!$AF$3:$AF$41
Name _30.b: April!$C$3:$H$41
Name _30.s: [1]April!$C$41:$H$41,[1]April!#REF!
Name _30.s: April!$C$41:$H$41,April!#REF!

Sheet Phased P&L Budget (2)
B2: Phased P&L Summary Report (Budget)
B3: Hotel Set: LH AG 2024
B4: Year: 2025
B5: With allocation
B6: P&L: Hotel Totals
B7: Currency: Euro
B8: Amounts: Full
B10: Budget | C10: Total Year | F10: Jan | I10: Feb | L10: Mar | O10: Apr | R10: May | U10: Jun | X10: Jul | AA10: Aug | AD10: Sep | AG10: Oct | AJ10: Nov | AM10: Dec
B11: Hotel Revenue | C11: 1.2198848e+08 | D11: 1 | F11: 7240087.4 | G11: 1 | I11: 8314846.3 | J11: 1 | L11: 11118561 | M11: 1 | O11: 8842420.1 | P11: 1 | R11: 11077677 | S11: 1 | U11: 10908122 | V11: 1 | X11: 9390566.3 | Y11: 1 | AA11: 10250151 | AB11: 1 | AD11: 12897676 | AE11: 1 | AG11: 12387225 | AH11: 1 | AJ11: 10794719 | AK11: 1 | AM11: 8766425.1 | AN11: 1
B12: P/R & Related Expenses | C12: 46975896 | D12: 0.3850847 | F12: 3792365.1 | G12: 0.52380101 | I12: 3908626 | J12: 0.47007796 | L12: 4046732.6 | M12: 0.36396191 | O12: 3846189 | P12: 0.43497018 | R12: 3937724.8 | S12: 0.35546484 | U12: 4039104.3 | V12: 0.37028412 | X12: 3752530.1 | Y12: 0.39960637 | AA12: 3776933.8 | AB12: 0.36847591 | AD12: 3995896.8 | AE12: 0.30981526 | AG12: 3933104.2 | AH12: 0.31751293 | AJ12: 4146594.9 | AK12: 0.38413181 | AM12: 3800094.4 | AN12: 0.43348279
B13: Gross Operating Profit | C13: 30075829 | D13: 0 | F13: 290044.42 | G13: 0 | I13: 889605.51 | J13: 0 | L13: 2812348.5 | M13: 0 | O13: 1496788.2 | P13: 0 | R13: 3386770.1 | S13: 0 | U13: 2841946.4 | V13: 0 | X13: 2276610.5 | Y13: 0 | AA13: 2905225.8 | AB13: 0 | AD13: 4624136 | AE13: 0 | AG13: 4442699.8 | AH13: 0 | AJ13: 2818991.9 | AK13: 0 | AM13: 1290661.9 | AN13: 0
B14: Available Rooms | C14: 824900 | D14: 0 | F14: 70060 | G14: 0 | I14: 63280 | J14: 0 | L14: 70060 | M14: 0 | O14: 67800 | P14: 0 | R14: 70060 | S14: 0 | U14: 67800 | V14: 0 | X14: 70060 | Y14: 0 | AA14: 70060 | AB14: 0 | AD14: 67800 | AE14: 0 | AG14: 70060 | AH14: 0 | AJ14: 67800 | AK14: 0 | AM14: 70060 | AN14: 0
B15: Rooms Sold | C15: 540060 | D15: 0 | F15: 36033 | G15: 0 | I15: 39507 | J15: 0 | L15: 49055 | M15: 0 | O15: 41789 | P15: 0 | R15: 47550 | S15: 0 | U15: 47041 | V15: 0 | X15: 42384 | Y15: 0 | AA15: 46032 | AB15: 0 | AD15: 52526 | AE15: 0 | AG15: 49112 | AH15: 0 | AJ15: 48568 | AK15: 0 | AM15: 40463 | AN15: 0
B16: Occupancy % | C16: 65.813311 | D16: 0 | F16: 51.772766 | G16: 0 | I16: 62.923515 | J16: 0 | L16: 70.342564 | M16: 0 | O16: 62.010324 | P16: 0 | R16: 68.305738 | S16: 0 | U16: 69.824484 | V16: 0 | X16: 60.852127 | Y16: 0 | AA16: 66.074793 | AB16: 0 | AD16: 77.817109 | AE16: 0 | AG16: 70.324008 | AH16: 0 | AJ16: 71.883481 | AK16: 0 | AM16: 57.93891 | AN16: 0
B17: Average Daily Rate | C17: 132.71698 | D17: 0 | F17: 114.80619 | G17: 0 | I17: 121.51362 | J17: 0 | L17: 138.74132 | M17: 0 | O17: 123.40963 | P17: 0 | R17: 141.99155 | S17: 0 | U17: 132.54899 | V17: 0 | X17: 123.94446 | Y17: 0 | AA17: 127.6863 | AB17: 0 | AD17: 142.64024 | AE17: 0 | AG17: 157.60431 | AH17: 0 | AJ17: 133.28359 | AK17: 0 | AM17: 122.35399 | AN17: 0
B18: Revenue Per Available Room | C18: 85.627391 | D18: 0 | F18: 57.891971 | G18: 0 | I18: 74.54233 | J18: 0 | L18: 95.72945 | M18: 0 | O18: 74.821758 | P18: 0 | R18: 95.038515 | S18: 0 | U18: 90.696713 | V18: 0 | X18: 73.926808 | Y18: 0 | AA18: 82.742015 | AB18: 0 | AD18: 109.06964 | AE18: 0 | AG18: 109.01174 | AH18: 0 | AJ18: 94.157338 | AK18: 0 | AM18: 69.673985 | AN18: 0
B19: Total Revenue Per Available Room | C19: 147.88274 | D19: 0 | F19: 103.34124 | G19: 0 | I19: 131.3977 | J19: 0 | L19: 158.70055 | M19: 0 | O19: 130.41917 | P19: 0 | R19: 158.117 | S19: 0 | U19: 160.88676 | V19: 0 | X19: 134.03606 | Y19: 0 | AA19: 146.30533 | AB19: 0 | AD19: 190.23121 | AE19: 0 | AG19: 176.80881 | AH19: 0 | AJ19: 159.21414 | AK19: 0 | AM19: 125.12739 | AN19: 0
B20: Number of Guests | C20: 744636.92 | D20: 0 | F20: 46243.555 | G20: 0 | I20: 51902.211 | J20: 0 | L20: 65871.502 | M20: 0 | O20: 56416.151 | P20: 0 | R20: 65738.666 | S20: 0 | U20: 64694.092 | V20: 0 | X20: 62619.382 | Y20: 0 | AA20: 68425.839 | AB20: 0 | AD20: 71191.698 | AE20: 0 | AG20: 69161.3 | AH20: 0 | AJ20: 63404.9 | AK20: 0 | AM20: 58967.63 | AN20: 0
B21: Room Density | C21: 1.3716065 | D21: 0 | F21: 1.2749105 | G21: 0 | I21: 1.3034861 | J21: 0 | L21: 1.336624 | M21: 0 | O21: 1.3418679 | P21: 0 | R21: 1.3737053 | S21: 0 | U21: 1.3665553 | V21: 0 | X21: 1.4688007 | Y21: 0 | AA21: 1.4781353 | AB21: 0 | AD21: 1.3493499 | AE21: 0 | AG21: 1.4037488 | AH21: 0 | AJ21: 1.3009603 | AK21: 0 | AM21: 1.4526909 | AN21: 0
B22: Covers | C22: 887397.83 | D22: 0 | F22: 57581.77 | G22: 0 | I22: 64906.699 | J22: 0 | L22: 76338.346 | M22: 0 | O22: 68538.039 | P22: 0 | R22: 76858.808 | S22: 0 | U22: 74693.977 | V22: 0 | X22: 69081.764 | Y22: 0 | AA22: 79196.073 | AB22: 0 | AD22: 88605.096 | AE22: 0 | AG22: 85343.551 | AH22: 0 | AJ22: 79676.765 | AK22: 0 | AM22: 66576.942 | AN22: 0
B23: FTE | C23: 626.5569 | D23: 0 | F23: 628.0784 | G23: 0 | I23: 636.6784 | J23: 0 | L23: 637.1784 | M23: 0 | O23: 629.8284 | P23: 0 | R23: 632.3284 | S23: 0 | U23: 629.3284 | V23: 0 | X23: 624.6684 | Y23: 0 | AA23: 624.3184 | AB23: 0 | AD23: 618.3184 | AE23: 0 | AG23: 619.3184 | AH23: 0 | AJ23: 619.3184 | AK23: 0 | AM23: 619.3184 | AN23: 0
B25: Hotel Totals
B27: Hotel Revenue | C27: 1.2198848e+08 | D27: 1 | F27: 7240087.4 | G27: 1 | I27: 8314846.3 | J27: 1 | L27: 11118561 | M27: 1 | O27: 8842420.1 | P27: 1 | R27: 11077677 | S27: 1 | U27: 10908122 | V27: 1 | X27: 9390566.3 | Y27: 1 | AA27: 10250151 | AB27: 1 | AD27: 12897676 | AE27: 1 | AG27: 12387225 | AH27: 1 | AJ27: 10794719 | AK27: 1 | AM27: 8766425.1 | AN27: 1
B28: Rooms Revenue | C28: 71675135 | D28: 0.5875566 | F28: 4136811.5 | G28: 0.57137591 | I28: 4800638.6 | J28: 0.57735747 | L28: 6805955.3 | M28: 0.61212557 | O28: 5157165.2 | P28: 0.58323006 | R28: 6751698.4 | S28: 0.60948683 | U28: 6235237.1 | V28: 0.57161417 | X28: 5253262.2 | Y28: 0.5594191 | AA28: 5877655.6 | AB28: 0.57342135 | AD28: 7492321.3 | AE28: 0.58090476 | AG28: 7740262.6 | AH28: 0.62485847 | AJ28: 6473317.5 | AK28: 0.59967449 | AM28: 4950809.4 | AN28: 0.56474667
B29: F&B Revenue | C29: 27110904 | D29: 0.22224152 | F29: 1845934.3 | G29: 0.25496023 | I29: 2166474.9 | J29: 0.26055501 | L29: 2499682.7 | M29: 0.22482071 | O29: 2111881.7 | P29: 0.23883526 | R29: 2284825.8 | S29: 0.20625495 | U29: 2341321.6 | V29: 0.21464021 | X29: 1757392.8 | Y29: 0.1871445 | AA29: 1960046.4 | AB29: 0.19122122 | AD29: 2945980.5 | AE29: 0.22841174 | AG29: 2550905 | AH29: 0.2059303 | AJ29: 2675403 | AK29: 0.24784369 | AM29: 1971055.6 | AN29: 0.22484143
B30: OOD Revenue | C30: 4283822.8 | D30: 0.03511662 | F30: 286832.35 | G30: 0.03961725 | I30: 324057.59 | J30: 0.03897337 | L30: 363546.36 | M30: 0.03269725 | O30: 338467.57 | P30: 0.03827771 | R30: 398241.14 | S30: 0.03594988 | U30: 383543.99 | V30: 0.03516132 | X30: 368802.63 | Y30: 0.03927374 | AA30: 378084.88 | AB30: 0.03688579 | AD30: 408861.68 | AE30: 0.03170042 | AG30: 375262.87 | AH30: 0.03029434 | AJ30: 348985.92 | AK30: 0.03232932 | AM30: 309135.81 | AN30: 0.03526361
B31: Other Income | C31: 1174894.8 | D31: 0.00963119 | F31: 75497.384 | G31: 0.01042769 | I31: 76366.258 | J31: 0.00918433 | L31: 140783.64 | M31: 0.01266204 | O31: 81646.668 | P31: 0.00923352 | R31: 84491.499 | S31: 0.00762719 | U31: 98406.032 | V31: 0.00902135 | X31: 69740.03 | Y31: 0.00742661 | AA31: 74394.707 | AB31: 0.00725791 | AD31: 130622.83 | AE31: 0.01012763 | AG31: 145234.84 | AH31: 0.01172457 | AJ31: 123977.66 | AK31: 0.01148503 | AM31: 73733.238 | AN31: 0.00841087
B33: Rooms
B34: Rooms Revenue | C34: 71675135 | D34: 1 | F34: 4136811.5 | G34: 1 | I34: 4800638.6 | J34: 1 | L34: 6805955.3 | M34: 1 | O34: 5157165.2 | P34: 1 | R34: 6751698.4 | S34: 1 | U34: 6235237.1 | V34: 1 | X34: 5253262.2 | Y34: 1 | AA34: 5877655.6 | AB34: 1 | AD34: 7492321.3 | AE34: 1 | AG34: 7740262.6 | AH34: 1 | AJ34: 6473317.5 | AK34: 1 | AM34: 4950809.4 | AN34: 1
B35: P/R & Related Expenses | C35: 14927382 | D35: 0.20826445 | F35: 1150985.7 | G35: 0.27823015 | I35: 1195591.5 | J35: 0.24904843 | L35: 1263390.6 | M35: 0.18563017 | O35: 1199755.4 | P35: 0.23263854 | R35: 1254052.2 | S35: 0.18573878 | U35: 1308248 | V35: 0.20981527 | X35: 1209968 | Y35: 0.23032697 | AA35: 1224281.5 | AB35: 0.20829419 | AD35: 1308659.8 | AE35: 0.1746668 | AG35: 1265785.9 | AH35: 0.16353268 | AJ35: 1331244.6 | AK35: 0.20565106 | AM35: 1215419.4 | AN35: 0.24549913
B36: Other Expenses | C36: 11316500 | D36: 0.15788599 | F36: 699808.76 | G36: 0.16916622 | I36: 798402.26 | J36: 0.16631168 | L36: 1064316.5 | M36: 0.15638018 | O36: 833095.11 | P36: 0.16154129 | R36: 1008530.1 | S36: 0.14937429 | U36: 1009980.4 | V36: 0.16197947 | X36: 892610.81 | Y36: 0.16991553 | AA36: 975216.27 | AB36: 0.16591926 | AD36: 1141191.3 | AE36: 0.15231478 | AG36: 1124487.9 | AH36: 0.14527774 | AJ36: 978351.73 | AK36: 0.15113606 | AM36: 790508.56 | AN36: 0.15967259
B37: Dept Profit/(Loss) | C37: 45431253 | D37: 0.63384956 | F37: 2286017.1 | G37: 0.55260363 | I37: 2806644.8 | J37: 0.58463989 | L37: 4478248.2 | M37: 0.65798965 | O37: 3124314.7 | P37: 0.60582017 | R37: 4489116.1 | S37: 0.66488694 | U37: 3917008.7 | V37: 0.62820525 | X37: 3150683.4 | Y37: 0.59975751 | AA37: 3678157.8 | AB37: 0.62578655 | AD37: 5042470.2 | AE37: 0.67301842 | AG37: 5349988.9 | AH37: 0.69118958 | AJ37: 4163721.2 | AK37: 0.64321288 | AM37: 2944881.4 | AN37: 0.59482828
B39: Food & Beverage
B40: Food Revenue | C40: 16634038 | D40: 0.61355526 | F40: 1107459.2 | G40: 0.59994508 | I40: 1274039.1 | J40: 0.58807011 | L40: 1523950.2 | M40: 0.60965746 | O40: 1288151.7 | P40: 0.60995448 | R40: 1414044.2 | S40: 0.61888493 | U40: 1445661.4 | V40: 0.61745528 | X40: 1107692.2 | Y40: 0.6303043 | AA40: 1242505.1 | AB40: 0.63391618 | AD40: 1825679.6 | AE40: 0.61971883 | AG40: 1583715 | AH40: 0.62084437 | AJ40: 1603559.3 | AK40: 0.59937114 | AM40: 1217580.8 | AN40: 0.61773031
B41: Beverage Revenue | C41: 7486725.1 | D41: 0.2761518 | F41: 500796.29 | G41: 0.27129692 | I41: 639110.17 | J41: 0.29500004 | L41: 714857.09 | M41: 0.28597913 | O41: 597059.2 | P41: 0.28271433 | R41: 623253.13 | S41: 0.27277928 | U41: 629867.8 | V41: 0.26902233 | X41: 497756.89 | Y41: 0.28323599 | AA41: 570157 | AB41: 0.29088954 | AD41: 765251.86 | AE41: 0.25976134 | AG41: 677870.49 | AH41: 0.26573726 | AJ41: 727029.87 | AK41: 0.27174593 | AM41: 543715.3 | AN41: 0.27584981
B42: Other Revenue | C42: 2990141.2 | D42: 0.11029294 | F42: 237678.82 | G42: 0.12875801 | I42: 253325.58 | J42: 0.11692985 | L42: 260875.43 | M42: 0.10436342 | O42: 226670.78 | P42: 0.10733119 | R42: 247528.4 | S42: 0.10833579 | U42: 265792.42 | V42: 0.11352239 | X42: 151943.67 | Y42: 0.08645971 | AA42: 147384.28 | AB42: 0.07519428 | AD42: 355049.07 | AE42: 0.12051983 | AG42: 289319.49 | AH42: 0.11341837 | AJ42: 344813.78 | AK42: 0.12888293 | AM42: 209759.51 | AN42: 0.10641989
B43: F&B Revenue | C43: 27110904 | D43: 1 | F43: 1845934.3 | G43: 1 | I43: 2166474.9 | J43: 1 | L43: 2499682.7 | M43: 1 | O43: 2111881.7 | P43: 1 | R43: 2284825.8 | S43: 1 | U43: 2341321.6 | V43: 1 | X43: 1757392.8 | Y43: 1 | AA43: 1960046.4 | AB43: 1 | AD43: 2945980.5 | AE43: 1 | AG43: 2550905 | AH43: 1 | AJ43: 2675403 | AK43: 1 | AM43: 1971055.6 | AN43: 1
B44: Cost of Sales Food | C44: 5085929.5 | D44: 0.30575436 | F44: 333187.26 | G44: 0.30085737 | I44: 391538.56 | J44: 0.30732067 | L44: 465349.65 | M44: 0.30535752 | O44: 393745.48 | P44: 0.30566702 | R44: 431554.11 | S44: 0.30519138 | U44: 438140.12 | V44: 0.30307244 | X44: 347743.09 | Y44: 0.31393475 | AA44: 391621.19 | AB44: 0.31518678 | AD44: 552937.66 | AE44: 0.30286676 | AG44: 484700.43 | AH44: 0.30605282 | AJ44: 485892.95 | AK44: 0.30300903 | AM44: 369519.01 | AN44: 0.30348624
B45: Cost of Sales Beverage | C45: 1338622.2 | D45: 0.17879944 | F45: 88165.581 | G45: 0.17605079 | I45: 113913.77 | J45: 0.17823808 | L45: 127404.49 | M45: 0.17822372 | O45: 106416.21 | P45: 0.17823393 | R45: 112350.47 | S45: 0.1802646 | U45: 113728.08 | V45: 0.18055865 | X45: 90660.094 | Y45: 0.1821373 | AA45: 103337.54 | AB45: 0.181244 | AD45: 136041.7 | AE45: 0.17777376 | AG45: 120505.79 | AH45: 0.17777111 | AJ45: 128344.9 | AK45: 0.17653319 | AM45: 97753.636 | AN45: 0.17978828
B46: Other Cost | C46: 209170 | D46: 0.06995322 | F46: 17577 | G46: 0.07395274 | I46: 18470 | J46: 0.07291013 | L46: 21130 | M46: 0.08099651 | O46: 15530 | P46: 0.06851346 | R46: 15740 | S46: 0.06358866 | U46: 20265 | V46: 0.07624371 | X46: 12265 | Y46: 0.08072071 | AA46: 10018 | AB46: 0.06797197 | AD46: 25790 | AE46: 0.07263785 | AG46: 17110 | AH46: 0.05913877 | AJ46: 21720 | AK46: 0.06299052 | AM46: 13555 | AN46: 0.06462162
...

Sheet Reporting
A1: Reporting zur Liquidität | B1: 45800
A2: LH AG 2025 | B2: December | F2: January | J2: February | N2: March | R2: April | V2: Mai | Z2: June | AD2: Sum
B3: Actual | C3: Plan | D3: Diff | F3: Actual | G3: Plan | H3: Diff | J3: Actual | K3: Plan | L3: Diff | N3: Actual | O3: Plan | P3: Diff | R3: Actual | S3: Plan | T3: Diff | V3: Actual | W3: Plan | X3: Diff | Z3: Actual | AA3: Plan | AB3: Diff | AD3: Diff
A5: Opening Balance | B5: =Dezember24!R4 -> 3000000 | C5: 3000000 | D5: =B5-'Exec.Summary_Liquiplanung ORG'!B4 -> 0 | F5: =Januar!B4 -> 3442499.7 | G5: 4761468.8 | H5: =F5-'Exec.Summary_Liquiplanung ORG'!C4 -> -1318969 | J5: =Februar!B4 -> 4095387.8 | K5: 6114525.2 | L5: =J5-'Exec.Summary_Liquiplanung ORG'!D4 -> -2019137.4 | N5: =März!B6 -> 4710438.2 | O5: 6704388.9 | P5: =N5-'Exec.Summary_Liquiplanung ORG'!E4 -> -1993950.7 | R5: =April!B4 -> 8081456.3 | S5: 5525812.8 | T5: =R5-'Exec.Summary_Liquiplanung ORG'!F4 -> 2555643.5 | V5: =Mai!B4 -> 10995169 | W5: 4526136.2 | X5: =V5-'Exec.Summary_Liquiplanung ORG'!G4 -> 6469033.1 | Z5: =Juni!B4 -> 9104878.3 | AA5: 4258286.9 | AB5: =Z5-'Exec.Summary_Liquiplanung ORG'!H4 -> 4846591.4
A6: Tagesgeld | B6: =Dezember24!AH5 -> 0 | C6: 0 | D6: =B6-'Exec.Summary_Liquiplanung ORG'!B5 -> 0 | F6: =Januar!AH5 -> 0 | G6: 0 | H6: =F6-'Exec.Summary_Liquiplanung ORG'!C5 -> 0 | J6: =Februar!AH5 -> 0 | K6: 0 | L6: =J6-'Exec.Summary_Liquiplanung ORG'!D5 -> 0 | N6: =März!AH5 -> 0 | O6: 0 | P6: =N6-'Exec.Summary_Liquiplanung ORG'!E5 -> 0 | R6: =April!AH5 -> 0 | S6: 0 | T6: =R6-'Exec.Summary_Liquiplanung ORG'!F5 -> 0 | V6: =Mai!AH5 -> 0 | W6: 0 | X6: =V6-'Exec.Summary_Liquiplanung ORG'!G5 -> 0 | Z6: =Juni!AH5 -> 0 | AA6: 0 | AB6: =Z6-'Exec.Summary_Liquiplanung ORG'!H5 -> 0
A7: Summe | B7: =Dezember24!AH6 -> 0 | C7: 0 | D7: =B7-'Exec.Summary_Liquiplanung ORG'!B6 -> 0 | F7: =Januar!AH6 -> 3442499.7 | G7: 4761468.8 | H7: =F7-'Exec.Summary_Liquiplanung ORG'!C6 -> -1318969 | J7: =Februar!AH6 -> 4095387.8 | K7: 6114525.2 | L7: =J7-'Exec.Summary_Liquiplanung ORG'!D6 -> -2019137.4 | N7: =März!AH6 -> 4710438.2 | O7: 6704388.9 | P7: =N7-'Exec.Summary_Liquiplanung ORG'!E6 -> -1993950.7 | R7: =April!AH6 -> 8081456.3 | S7: 5525812.8 | T7: =R7-'Exec.Summary_Liquiplanung ORG'!F6 -> 2555643.5 | V7: =Mai!AH6 -> 10995169 | W7: 4526136.2 | X7: =V7-'Exec.Summary_Liquiplanung ORG'!G6 -> 6469033.1 | Z7: =Juni!AH6 -> 9104878.3 | AA7: 4258286.9 | AB7: =Z7-'Exec.Summary_Liquiplanung ORG'!H6 -> 4846591.4
A8: AUSGABEN | V8: =Mai!AH7 | Z8: =Juni!AH7
A9: Pacht | B9: =Dezember24!AH8 -> 0 | C9: 0 | D9: =B9-'Exec.Summary_Liquiplanung ORG'!B8 -> 0 | F9: =Januar!AH8 -> 1336978.3 | G9: 1985625.6 | H9: =F9-'Exec.Summary_Liquiplanung ORG'!C8 -> -648647.27 | J9: =Februar!AH8 -> -227726.6 | K9: 0 | L9: =J9-'Exec.Summary_Liquiplanung ORG'!D8 -> -227726.6 | N9: =März!AH8 -> 1756520.4 | O9: 2155965.1 | P9: =N9-'Exec.Summary_Liquiplanung ORG'!E8 -> -399444.71 | R9: =April!AH8 -> 2715108 | S9: 1910266.6 | T9: =R9-'Exec.Summary_Liquiplanung ORG'!F8 -> 804841.39 | V9: =Mai!AH8 -> 3884517 | W9: 2025043.1 | X9: =V9-'Exec.Summary_Liquiplanung ORG'!G8 -> 1859473.9 | Z9: =Juni!AH8 -> 0 | AA9: 1910725.9 | AB9: =Z9-'Exec.Summary_Liquiplanung ORG'!H8 -> -1910725.9 | AD9: -621610.88 | AF9: Reduktion der Pachtzahlungen
A10: Annuität ext. | B10: =Dezember24!AH9 -> 0 | C10: 0 | D10: =B10-'Exec.Summary_Liquiplanung ORG'!B9 -> 0 | F10: =Januar!AH9 -> 0 | G10: 0 | H10: =F10-'Exec.Summary_Liquiplanung ORG'!C9 -> 0 | J10: =Februar!AH9 -> 0 | K10: 0 | L10: =J10-'Exec.Summary_Liquiplanung ORG'!D9 -> 0 | N10: =März!AH9 -> 0 | O10: 0 | P10: =N10-'Exec.Summary_Liquiplanung ORG'!E9 -> 0 | R10: =April!AH9 -> 0 | S10: 0 | T10: =R10-'Exec.Summary_Liquiplanung ORG'!F9 -> 0 | V10: =Mai!AH9 -> 0 | W10: 0 | X10: =V10-'Exec.Summary_Liquiplanung ORG'!G9 -> 0 | Z10: =Juni!AH9 -> 0 | AA10: 0 | AB10: =Z10-'Exec.Summary_Liquiplanung ORG'!H9 -> 0 | AD10: 0
A11: Kreditorenzahlungen | B11: =Dezember24!AH10 -> 65390 | C11: 1250000 | D11: =B11-'Exec.Summary_Liquiplanung ORG'!B10 -> -1184610 | F11: =Januar!AH10 -> 2712411.1 | G11: 4050000 | H11: =F11-'Exec.Summary_Liquiplanung ORG'!C10 -> -1337588.9 | J11: =Februar!AH10 -> 5020228.1 | K11: 5142904.9 | L11: =J11-'Exec.Summary_Liquiplanung ORG'!D10 -> -122676.8 | N11: =März!AH10 -> 3209571.6 | O11: 6097028.3 | P11: =N11-'Exec.Summary_Liquiplanung ORG'!E10 -> -2887456.6 | R11: =April!AH10 -> 1978234.2 | S11: 4826493.1 | T11: =R11-'Exec.Summary_Liquiplanung ORG'!F10 -> -2848258.9 | V11: =Mai!AH10 -> 4806305 | W11: 5720424.9 | X11: =V11-'Exec.Summary_Liquiplanung ORG'!G10 -> -914119.98 | Z11: =Juni!AH10 -> 5122538.2 | AA11: 6099134.1 | AB11: =Z11-'Exec.Summary_Liquiplanung ORG'!H10 -> -976595.92 | AD11: -1397337.4 | AF11: Anpassung Kreditoren
A12: Aktivbank/Progros | B12: =Dezember24!AH11 -> 0 | C12: 0 | D12: =B12-'Exec.Summary_Liquiplanung ORG'!B11 -> 0 | F12: =Januar!AH11 -> 80069 | G12: 0 | H12: =F12-'Exec.Summary_Liquiplanung ORG'!C11 -> 80069 | J12: =Februar!AH11 -> 0 | K12: 0 | L12: =J12-'Exec.Summary_Liquiplanung ORG'!D11 -> 0 | N12: =März!AH11 -> 0 | O12: 0 | P12: =N12-'Exec.Summary_Liquiplanung ORG'!E11 -> 0 | R12: =April!AH11 -> 0 | S12: 0 | T12: =R12-'Exec.Summary_Liquiplanung ORG'!F11 -> 0 | V12: =Mai!AH11 -> 0 | W12: 0 | X12: =V12-'Exec.Summary_Liquiplanung ORG'!G11 -> 0 | Z12: =Juni!AH11 -> 0 | AA12: 0 | AB12: =Z12-'Exec.Summary_Liquiplanung ORG'!H11 -> 0 | AD12: 80069
A13: Lastschriften | B13: =Dezember24!AH12 -> 0 | C13: 0 | D13: =B13-'Exec.Summary_Liquiplanung ORG'!B12 -> 0 | F13: =Januar!AH12 -> 541051.79 | G13: 0 | H13: =F13-'Exec.Summary_Liquiplanung ORG'!C12 -> 541051.79 | J13: =Februar!AH12 -> 0 | K13: 0 | L13: =J13-'Exec.Summary_Liquiplanung ORG'!D12 -> 0 | N13: =März!AH12 -> 0 | O13: 0 | P13: =N13-'Exec.Summary_Liquiplanung ORG'!E12 -> 0 | R13: =April!AH12 -> 0 | S13: 0 | T13: =R13-'Exec.Summary_Liquiplanung ORG'!F12 -> 0 | V13: =Mai!AH12 -> 0 | W13: 0 | X13: =V13-'Exec.Summary_Liquiplanung ORG'!G12 -> 0 | Z13: =Juni!AH12 -> 0 | AA13: 0 | AB13: =Z13-'Exec.Summary_Liquiplanung ORG'!H12 -> 0 | AD13: 541051.79
A14: Energiedienstleister | B14: =Dezember24!AH13 -> 0 | C14: 0 | D14: =B14-'Exec.Summary_Liquiplanung ORG'!B13 -> 0 | F14: =Januar!AH13 -> 148000 | G14: 0 | H14: =F14-'Exec.Summary_Liquiplanung ORG'!C13 -> 148000 | J14: =Februar!AH13 -> 0 | K14: 0 | L14: =J14-'Exec.Summary_Liquiplanung ORG'!D13 -> 0 | N14: =März!AH13 -> 0 | O14: 0 | P14: =N14-'Exec.Summary_Liquiplanung ORG'!E13 -> 0 | R14: =April!AH13 -> 0 | S14: 0 | T14: =R14-'Exec.Summary_Liquiplanung ORG'!F13 -> 0 | V14: =Mai!AH13 -> 0 | W14: 0 | X14: =V14-'Exec.Summary_Liquiplanung ORG'!G13 -> 0 | Z14: =Juni!AH13 -> 0 | AA14: 0 | AB14: =Z14-'Exec.Summary_Liquiplanung ORG'!H13 -> 0 | AD14: 148000
A15: Telekommunikation | B15: =Dezember24!AH14 -> 0 | C15: 0 | D15: =B15-'Exec.Summary_Liquiplanung ORG'!B14 -> 0 | F15: =Januar!AH14 -> 393051.79 | G15: 0 | H15: =F15-'Exec.Summary_Liquiplanung ORG'!C14 -> 393051.79 | J15: =Februar!AH14 -> 0 | K15: 0 | L15: =J15-'Exec.Summary_Liquiplanung ORG'!D14 -> 0 | N15: =März!AH14 -> 0 | O15: 0 | P15: =N15-'Exec.Summary_Liquiplanung ORG'!E14 -> 0 | R15: =April!AH14 -> 0 | S15: 0 | T15: =R15-'Exec.Summary_Liquiplanung ORG'!F14 -> 0 | V15: =Mai!AH14 -> 0 | W15: 0 | X15: =V15-'Exec.Summary_Liquiplanung ORG'!G14 -> 0 | Z15: =Juni!AH14 -> 0 | AA15: 0 | AB15: =Z15-'Exec.Summary_Liquiplanung ORG'!H14 -> 0 | AD15: 393051.79
A16: Gebühren CC | B16: =Dezember24!AH15 -> 0 | C16: 0 | D16: =B16-'Exec.Summary_Liquiplanung ORG'!B15 -> 0 | F16: =Januar!AH15 -> 0 | G16: 0 | H16: =F16-'Exec.Summary_Liquiplanung ORG'!C15 -> 0 | J16: =Februar!AH15 -> 0 | K16: 0 | L16: =J16-'Exec.Summary_Liquiplanung ORG'!D15 -> 0 | N16: =März!AH15 -> 0 | O16: 0 | P16: =N16-'Exec.Summary_Liquiplanung ORG'!E15 -> 0 | R16: =April!AH15 -> 0 | S16: 0 | T16: =R16-'Exec.Summary_Liquiplanung ORG'!F15 -> 0 | V16: =Mai!AH15 -> 0 | W16: 0 | X16: =V16-'Exec.Summary_Liquiplanung ORG'!G15 -> 0 | Z16: =Juni!AH15 -> 0 | AA16: 0 | AB16: =Z16-'Exec.Summary_Liquiplanung ORG'!H15 -> 0 | AD16: 0
A17: Provisonen( Booking, Expedia | B17: =Dezember24!AH16 -> 0 | C17: 0 | D17: =B17-'Exec.Summary_Liquiplanung ORG'!B16 -> 0 | F17: =Januar!AH16 -> 0 | G17: 0 | H17: =F17-'Exec.Summary_Liquiplanung ORG'!C16 -> 0 | J17: =Februar!AH16 -> 0 | K17: 0 | L17: =J17-'Exec.Summary_Liquiplanung ORG'!D16 -> 0 | N17: =März!AH16 -> 0 | O17: 0 | P17: =N17-'Exec.Summary_Liquiplanung ORG'!E16 -> 0 | R17: =April!AH16 -> 0 | S17: 0 | T17: =R17-'Exec.Summary_Liquiplanung ORG'!F16 -> 0 | V17: =Mai!AH16 -> 0 | W17: 0 | X17: =V17-'Exec.Summary_Liquiplanung ORG'!G16 -> 0 | Z17: =Juni!AH16 -> 0 | AA17: 0 | AB17: =Z17-'Exec.Summary_Liquiplanung ORG'!H16 -> 0 | AD17: 0
A18: KFZ Leasing | B18: =Dezember24!AH17 -> 0 | C18: 0 | D18: =B18-'Exec.Summary_Liquiplanung ORG'!B17 -> 0 | F18: =Januar!AH17 -> 0 | G18: 0 | H18: =F18-'Exec.Summary_Liquiplanung ORG'!C17 -> 0 | J18: =Februar!AH17 -> 0 | K18: 0 | L18: =J18-'Exec.Summary_Liquiplanung ORG'!D17 -> 0 | N18: =März!AH17 -> 0 | O18: 0 | P18: =N18-'Exec.Summary_Liquiplanung ORG'!E17 -> 0 | R18: =April!AH17 -> 0 | S18: 0 | T18: =R18-'Exec.Summary_Liquiplanung ORG'!F17 -> 0 | V18: =Mai!AH17 -> 0 | W18: 0 | X18: =V18-'Exec.Summary_Liquiplanung ORG'!G17 -> 0 | Z18: =Juni!AH17 -> 0 | AA18: 0 | AB18: =Z18-'Exec.Summary_Liquiplanung ORG'!H17 -> 0 | AD18: 0
A19: Jobtickets | B19: =Dezember24!AH18 -> 0 | C19: 0 | D19: =B19-'Exec.Summary_Liquiplanung ORG'!B18 -> 0 | F19: =Januar!AH18 -> 0 | G19: 0 | H19: =F19-'Exec.Summary_Liquiplanung ORG'!C18 -> 0 | J19: =Februar!AH18 -> 0 | K19: 0 | L19: =J19-'Exec.Summary_Liquiplanung ORG'!D18 -> 0 | N19: =März!AH18 -> 0 | O19: 0 | P19: =N19-'Exec.Summary_Liquiplanung ORG'!E18 -> 0 | R19: =April!AH18 -> 0 | S19: 0 | T19: =R19-'Exec.Summary_Liquiplanung ORG'!F18 -> 0 | V19: =Mai!AH18 -> 0 | W19: 0 | X19: =V19-'Exec.Summary_Liquiplanung ORG'!G18 -> 0 | Z19: =Juni!AH18 -> 0 | AA19: 0 | AB19: =Z19-'Exec.Summary_Liquiplanung ORG'!H18 -> 0 | AD19: 0
A20: Leasing | B20: =Dezember24!AH19 -> 0 | C20: 0 | D20: =B20-'Exec.Summary_Liquiplanung ORG'!B19 -> 0 | F20: =Januar!AH19 -> 0 | G20: 0 | H20: =F20-'Exec.Summary_Liquiplanung ORG'!C19 -> 0 | J20: =Februar!AH19 -> 0 | K20: 0 | L20: =J20-'Exec.Summary_Liquiplanung ORG'!D19 -> 0 | N20: =März!AH19 -> 0 | O20: 0 | P20: =N20-'Exec.Summary_Liquiplanung ORG'!E19 -> 0 | R20: =April!AH19 -> 0 | S20: 0 | T20: =R20-'Exec.Summary_Liquiplanung ORG'!F19 -> 0 | V20: =Mai!AH19 -> 0 | W20: 0 | X20: =V20-'Exec.Summary_Liquiplanung ORG'!G19 -> 0 | Z20: =Juni!AH19 -> 0 | AA20: 0 | AB20: =Z20-'Exec.Summary_Liquiplanung ORG'!H19 -> 0 | AD20: 0
A21: Gema/GEZ/Sky | B21: =Dezember24!AH20 -> 0 | C21: 0 | D21: =B21-'Exec.Summary_Liquiplanung ORG'!B20 -> 0 | F21: =Januar!AH20 -> 0 | G21: 0 | H21: =F21-'Exec.Summary_Liquiplanung ORG'!C20 -> 0 | J21: =Februar!AH20 -> 0 | K21: 0 | L21: =J21-'Exec.Summary_Liquiplanung ORG'!D20 -> 0 | N21: =März!AH20 -> 0 | O21: 0 | P21: =N21-'Exec.Summary_Liquiplanung ORG'!E20 -> 0 | R21: =April!AH20 -> 0 | S21: 0 | T21: =R21-'Exec.Summary_Liquiplanung ORG'!F20 -> 0 | V21: =Mai!AH20 -> 0 | W21: 0 | X21: =V21-'Exec.Summary_Liquiplanung ORG'!G20 -> 0 | Z21: =Juni!AH20 -> 0 | AA21: 0 | AB21: =Z21-'Exec.Summary_Liquiplanung ORG'!H20 -> 0 | AD21: 0
A22: Sonepar/Haustechnik | B22: =Dezember24!AH21 -> 0 | C22: 0 | D22: =B22-'Exec.Summary_Liquiplanung ORG'!B21 -> 0 | F22: =Januar!AH21 -> 0 | G22: 0 | H22: =F22-'Exec.Summary_Liquiplanung ORG'!C21 -> 0 | J22: =Februar!AH21 -> 0 | K22: 0 | L22: =J22-'Exec.Summary_Liquiplanung ORG'!D21 -> 0 | N22: =März!AH21 -> 0 | O22: 0 | P22: =N22-'Exec.Summary_Liquiplanung ORG'!E21 -> 0 | R22: =April!AH21 -> 0 | S22: 0 | T22: =R22-'Exec.Summary_Liquiplanung ORG'!F21 -> 0 | V22: =Mai!AH21 -> 0 | W22: 0 | X22: =V22-'Exec.Summary_Liquiplanung ORG'!G21 -> 0 | Z22: =Juni!AH21 -> 0 | AA22: 0 | AB22: =Z22-'Exec.Summary_Liquiplanung ORG'!H21 -> 0 | AD22: 0
A23: Airplus | B23: =Dezember24!AH22 -> 0 | C23: 0 | D23: =B23-'Exec.Summary_Liquiplanung ORG'!B22 -> 0 | F23: =Januar!AH22 -> 0 | G23: 0 | H23: =F23-'Exec.Summary_Liquiplanung ORG'!C22 -> 0 | J23: =Februar!AH22 -> 0 | K23: 0 | L23: =J23-'Exec.Summary_Liquiplanung ORG'!D22 -> 0 | N23: =März!AH22 -> 0 | O23: 0 | P23: =N23-'Exec.Summary_Liquiplanung ORG'!E22 -> 0 | R23: =April!AH22 -> 0 | S23: 0 | T23: =R23-'Exec.Summary_Liquiplanung ORG'!F22 -> 0 | V23: =Mai!AH22 -> 0 | W23: 0 | X23: =V23-'Exec.Summary_Liquiplanung ORG'!G22 -> 0 | Z23: =Juni!AH22 -> 0 | AA23: 0 | AB23: =Z23-'Exec.Summary_Liquiplanung ORG'!H22 -> 0 | AD23: 0
A24: BGN/Schwerbeh.abgabe | B24: =Dezember24!AH23 -> 0 | C24: 0 | D24: =B24-'Exec.Summary_Liquiplanung ORG'!B23 -> 0 | F24: =Januar!AH23 -> 0 | G24: 60000 | H24: =F24-'Exec.Summary_Liquiplanung ORG'!C23 -> -60000 | J24: =Februar!AH23 -> 0 | K24: 0 | L24: =J24-'Exec.Summary_Liquiplanung ORG'!D23 -> 0 | N24: =März!AH23 -> 60000 | O24: 60000 | P24: =N24-'Exec.Summary_Liquiplanung ORG'!E23 -> 0 | R24: =April!AH23 -> 0 | S24: 0 | T24: =R24-'Exec.Summary_Liquiplanung ORG'!F23 -> 0 | V24: =Mai!AH23 -> 60000 | W24: 60000 | X24: =V24-'Exec.Summary_Liquiplanung ORG'!G23 -> 0 | Z24: =Juni!AH23 -> 0 | AA24: 0 | AB24: =Z24-'Exec.Summary_Liquiplanung ORG'!H23 -> 0 | AD24: -60000
A25: interne Zahlungen | B25: =Dezember24!AH24 -> 0 | C25: 0 | D25: =B25-'Exec.Summary_Liquiplanung ORG'!B24 -> 0 | F25: =Januar!AH24 -> 0 | G25: 100000 | H25: =F25-'Exec.Summary_Liquiplanung ORG'!C24 -> -100000 | J25: =Februar!AH24 -> 0 | K25: 100000 | L25: =J25-'Exec.Summary_Liquiplanung ORG'!D24 -> -100000 | N25: =März!AH24 -> 0 | O25: 100000 | P25: =N25-'Exec.Summary_Liquiplanung ORG'!E24 -> -100000 | R25: =April!AH24 -> 50000 | S25: 100000 | T25: =R25-'Exec.Summary_Liquiplanung ORG'!F24 -> -50000 | V25: =Mai!AH24 -> 50000 | W25: 100000 | X25: =V25-'Exec.Summary_Liquiplanung ORG'!G24 -> -50000 | Z25: =Juni!AH24 -> 50000 | AA25: 100000 | AB25: =Z25-'Exec.Summary_Liquiplanung ORG'!H24 -> -50000 | AD25: -300000 | AF25: Finanzierung von Tochtergesellschaften reduziert
A26: City Taxes | B26: =Dezember24!AH25 -> 0 | C26: 0 | D26: =B26-'Exec.Summary_Liquiplanung ORG'!B25 -> 0 | F26: =Januar!AH25 -> 0 | G26: 180000 | H26: =F26-'Exec.Summary_Liquiplanung ORG'!C25 -> -180000 | J26: =Februar!AH25 -> 0 | K26: 10000 | L26: =J26-'Exec.Summary_Liquiplanung ORG'!D25 -> -10000 | N26: =März!AH25 -> 0 | O26: 10000 | P26: =N26-'Exec.Summary_Liquiplanung ORG'!E25 -> -10000 | R26: =April!AH25 -> 250000 | S26: 250000 | T26: =R26-'Exec.Summary_Liquiplanung ORG'!F25 -> 0 | V26: =Mai!AH25 -> 265000 | W26: 20000 | X26: =V26-'Exec.Summary_Liquiplanung ORG'!G25 -> 245000 | Z26: =Juni!AH25 -> 0 | AA26: 0 | AB26: =Z26-'Exec.Summary_Liquiplanung ORG'!H25 -> 0 | AD26: -50000 | AF26: Anpassung an Umsatzerwartung
A27: L&G | B27: =Dezember24!AH26 -> 0 | C27: 170000 | D27: =B27-'Exec.Summary_Liquiplanung ORG'!B26 -> -170000 | F27: =Januar!AH26 -> 42140 | G27: 170000 | H27: =F27-'Exec.Summary_Liquiplanung ORG'!C26 -> -127860 | J27: =Februar!AH26 -> 170000 | K27: 170000 | L27: =J27-'Exec.Summary_Liquiplanung ORG'!D26 -> 0 | N27: =März!AH26 -> 1429283.5 | O27: 1550000 | P27: =N27-'Exec.Summary_Liquiplanung ORG'!E26 -> -120716.51 | R27: =April!AH26 -> 1500000 | S27: 1550000 | T27: =R27-'Exec.Summary_Liquiplanung ORG'!F26 -> -50000 | V27: =Mai!AH26 -> 1500000 | W27: 1550000 | X27: =V27-'Exec.Summary_Liquiplanung ORG'!G26 -> -50000 | Z27: =Juni!AH26 -> 1500000 | AA27: 1550000 | AB27: =Z27-'Exec.Summary_Liquiplanung ORG'!H26 -> -50000 | AD27: -359860 | AF27: Anpassung an Umsatzerwartung
A28: Krankenkasse | B28: =Dezember24!AH27 -> 0 | C28: 0 | D28: =B28-'Exec.Summary_Liquiplanung ORG'!B27 -> 0 | F28: =Januar!AH27 -> 0 | G28: 0 | H28: =F28-'Exec.Summary_Liquiplanung ORG'!C27 -> 0 | J28: =Februar!AH27 -> 0 | K28: 0 | L28: =J28-'Exec.Summary_Liquiplanung ORG'!D27 -> 0 | N28: =März!AH27 -> 805613.08 | O28: 850000 | P28: =N28-'Exec.Summary_Liquiplanung ORG'!E27 -> -44386.92 | R28: =April!AH27 -> 850000 | S28: 850000 | T28: =R28-'Exec.Summary_Liquiplanung ORG'!F27 -> 0 | V28: =Mai!AH27 -> 850000 | W28: 850000 | X28: =V28-'Exec.Summary_Liquiplanung ORG'!G27 -> 0 | Z28: =Juni!AH27 -> 850000 | AA28: 850000 | AB28: =Z28-'Exec.Summary_Liquiplanung ORG'!H27 -> 0 | AD28: 0
A29: Lohnsteuer | B29: =Dezember24!AH28 -> 0 | C29: 0 | D29: =B29-'Exec.Summary_Liquiplanung ORG'!B28 -> 0 | F29: =Januar!AH28 -> 0 | G29: 0 | H29: =F29-'Exec.Summary_Liquiplanung ORG'!C28 -> 0 | J29: =Februar!AH28 -> 0 | K29: 0 | L29: =J29-'Exec.Summary_Liquiplanung ORG'!D28 -> 0 | N29: =März!AH28 -> 551000 | O29: 350000 | P29: =N29-'Exec.Summary_Liquiplanung ORG'!E28 -> 201000 | R29: =April!AH28 -> 350000 | S29: 350000 | T29: =R29-'Exec.Summary_Liquiplanung ORG'!F28 -> 0 | V29: =Mai!AH28 -> 350000 | W29: 350000 | X29: =V29-'Exec.Summary_Liquiplanung ORG'!G28 -> 0 | Z29: =Juni!AH28 -> 350000 | AA29: 350000 | AB29: =Z29-'Exec.Summary_Liquiplanung ORG'!H28 -> 0 | AD29: 230000 | AF29: Anpassung an Umsatzerwartung
A30: UST | B30: =Dezember24!AH29 -> 0 | C30: 0 | D30: =B30-'Exec.Summary_Liquiplanung ORG'!B29 -> 0 | F30: =Januar!AH29 -> 0 | G30: -350314.99 | H30: =F30-'Exec.Summary_Liquiplanung ORG'!C29 -> 350314.99 | J30: =Februar!AH29 -> 0 | K30: -73565.065 | L30: =J30-'Exec.Summary_Liquiplanung ORG'!D29 -> 73565.065 | N30: =März!AH29 -> 0 | O30: -327098.98 | P30: =N30-'Exec.Summary_Liquiplanung ORG'!E29 -> 327098.98 | R30: =April!AH29 -> 166115.03 | S30: -318831.01 | T30: =R30-'Exec.Summary_Liquiplanung ORG'!F29 -> 484946.04 | V30: =Mai!AH29 -> 150000 | W30: -251345.76 | X30: =V30-'Exec.Summary_Liquiplanung ORG'!G29 -> 401345.76 | Z30: =Juni!AH29 -> 150000 | AA30: -296063.43 | AB30: =Z30-'Exec.Summary_Liquiplanung ORG'!H29 -> 446063.43 | AD30: 750980.23 | AF30: Ust Erstattung in Januar bis März nicht zu erwarten
A31: Berater-/ Verfahrenskosten Insolvenzverfahren | B31: =Dezember24!AH30 -> 0 | C31: 0 | D31: =B31-'Exec.Summary_Liquiplanung ORG'!B30 -> 0 | F31: =Januar!AH30 -> 0 | G31: 0 | H31: =F31-'Exec.Summary_Liquiplanung ORG'!C30 -> 0 | J31: =Februar!AH30 -> 1500000 | K31: 1500000 | L31: =J31-'Exec.Summary_Liquiplanung ORG'!D30 -> 0 | N31: =März!AH30 -> 0 | O31: 0 | P31: =N31-'Exec.Summary_Liquiplanung ORG'!E30 -> 0 | R31: =April!AH30 -> 0 | S31: 0 | T31: =R31-'Exec.Summary_Liquiplanung ORG'!F30 -> 0 | V31: =Mai!AH30 -> 0 | W31: 0 | X31: =V31-'Exec.Summary_Liquiplanung ORG'!G30 -> 0 | Z31: =Juni!AH30 -> 0 | AA31: 2400000 | AB31: =Z31-'Exec.Summary_Liquiplanung ORG'!H30 -> -2400000 | AD31: 0
A32: div. Abbuchungen | B32: =Dezember24!AH31 -> 0 | C32: 0 | D32: =B32-'Exec.Summary_Liquiplanung ORG'!B31 -> 0 | F32: =Januar!AH31 -> 0 | G32: 0 | H32: =F32-'Exec.Summary_Liquiplanung ORG'!C31 -> 0 | J32: =Februar!AH31 -> 98500 | K32: 0 | L32: =J32-'Exec.Summary_Liquiplanung ORG'!D31 -> 98500 | N32: =März!AH31 -> 0 | O32: 0 | P32: =N32-'Exec.Summary_Liquiplanung ORG'!E31 -> 0 | R32: =April!AH31 -> 0 | S32: 0 | T32: =R32-'Exec.Summary_Liquiplanung ORG'!F31 -> 0 | V32: =Mai!AH31 -> 0 | W32: 0 | X32: =V32-'Exec.Summary_Liquiplanung ORG'!G31 -> 0 | Z32: =Juni!AH31 -> 0 | AA32: 0 | AB32: =Z32-'Exec.Summary_Liquiplanung ORG'!H31 -> 0 | AD32: 0
A33: Summe Ausgaben | B33: =Dezember24!AH32 -> 65390 | C33: 1420000 | D33: =B33-'Exec.Summary_Liquiplanung ORG'!B32 -> -1354610 | F33: =Januar!AH32 -> 4712650.2 | G33: 6195310.6 | H33: =F33-'Exec.Summary_Liquiplanung ORG'!C32 -> -1482660.4 | J33: =Februar!AH32 -> 6561001.5 | K33: 6849339.9 | L33: =J33-'Exec.Summary_Liquiplanung ORG'!D32 -> -288338.33 | N33: =März!AH32 -> 7811988.6 | O33: 10845894 | P33: =N33-'Exec.Summary_Liquiplanung ORG'!E32 -> -3033905.8 | R33: =April!AH32 -> 7859457.2 | S33: 9517928.7 | T33: =R33-'Exec.Summary_Liquiplanung ORG'!F32 -> -1658471.4 | V33: =Mai!AH32 -> 11915822 | W33: 10424122 | X33: =V33-'Exec.Summary_Liquiplanung ORG'!G32 -> 1491699.7 | Z33: =Juni!AH32 -> 8022538.2 | AA33: 12963797 | AB33: =Z33-'Exec.Summary_Liquiplanung ORG'!H32 -> -4941258.4 | AD33: -1186707.3
D34: =B34-'Exec.Summary_Liquiplanung ORG'!B33 -> 0 | H34: =F34-'Exec.Summary_Liquiplanung ORG'!C33 -> 0 | L34: =J34-'Exec.Summary_Liquiplanung ORG'!D33 -> 0 | P34: =N34-'Exec.Summary_Liquiplanung ORG'!E33 -> 0 | T34: =R34-'Exec.Summary_Liquiplanung ORG'!F33 -> 0 | X34: =V34-'Exec.Summary_Liquiplanung ORG'!G33 -> 0 | AB34: =Z34-'Exec.Summary_Liquiplanung ORG'!H33 -> 0 | AD34: 0
A35: EINNAHMEN
A36: Vorauszahlungen | B36: =Dezember24!AH35 -> 0 | C36: 0 | D36: =B36-'Exec.Summary_Liquiplanung ORG'!B35 -> 0 | F36: =Januar!AH35 -> 0 | G36: 0 | H36: =F36-'Exec.Summary_Liquiplanung ORG'!C35 -> 0 | J36: =Februar!AH35 -> 0 | K36: 0 | L36: =J36-'Exec.Summary_Liquiplanung ORG'!D35 -> 0 | N36: =März!AH35 -> 0 | O36: 0 | P36: =N36-'Exec.Summary_Liquiplanung ORG'!E35 -> 0 | R36: =April!AH35 -> 0 | S36: 0 | T36: =R36-'Exec.Summary_Liquiplanung ORG'!F35 -> 0 | V36: =Mai!AH35 -> 0 | W36: 0 | X36: =V36-'Exec.Summary_Liquiplanung ORG'!G35 -> 0 | Z36: =Juni!AH35 -> 0 | AA36: 0 | AB36: =Z36-'Exec.Summary_Liquiplanung ORG'!H35 -> 0 | AD36: 0
A37: Bareinzahlungen | B37: =Dezember24!AH36 -> 0 | C37: 0 | D37: =B37-'Exec.Summary_Liquiplanung ORG'!B36 -> 0 | F37: =Januar!AH36 -> 0 | G37: 0 | H37: =F37-'Exec.Summary_Liquiplanung ORG'!C36 -> 0 | J37: =Februar!AH36 -> 0 | K37: 0 | L37: =J37-'Exec.Summary_Liquiplanung ORG'!D36 -> 0 | N37: =März!AH36 -> 0 | O37: 0 | P37: =N37-'Exec.Summary_Liquiplanung ORG'!E36 -> 0 | R37: =April!AH36 -> 0 | S37: 0 | T37: =R37-'Exec.Summary_Liquiplanung ORG'!F36 -> 0 | V37: =Mai!AH36 -> 0 | W37: 0 | X37: =V37-'Exec.Summary_Liquiplanung ORG'!G36 -> 0 | Z37: =Juni!AH36 -> 0 | AA37: 0 | AB37: =Z37-'Exec.Summary_Liquiplanung ORG'!H36 -> 0 | AD37: 0
A38: Umbuchungen S-Zentral | B38: =Dezember24!AH37 -> 0 | C38: 0 | D38: =B38-'Exec.Summary_Liquiplanung ORG'!B37 -> 0 | F38: =Januar!AH37 -> 0 | G38: 0 | H38: =F38-'Exec.Summary_Liquiplanung ORG'!C37 -> 0 | J38: =Februar!AH37 -> 0 | K38: 0 | L38: =J38-'Exec.Summary_Liquiplanung ORG'!D37 -> 0 | N38: =März!AH37 -> 0 | O38: 0 | P38: =N38-'Exec.Summary_Liquiplanung ORG'!E37 -> 0 | R38: =April!AH37 -> 0 | S38: 0 | T38: =R38-'Exec.Summary_Liquiplanung ORG'!F37 -> 0 | V38: =Mai!AH37 -> 0 | W38: 0 | X38: =V38-'Exec.Summary_Liquiplanung ORG'!G37 -> 0 | Z38: =Juni!AH37 -> 0 | AA38: 0 | AB38: =Z38-'Exec.Summary_Liquiplanung ORG'!H37 -> 0 | AD38: 0
A39: interne Zahlungen | B39: =Dezember24!AH38 -> 0 | C39: 0 | D39: =B39-'Exec.Summary_Liquiplanung ORG'!B38 -> 0 | F39: =Januar!AH38 -> 0 | G39: 0 | H39: =F39-'Exec.Summary_Liquiplanung ORG'!C38 -> 0 | J39: =Februar!AH38 -> 0 | K39: 0 | L39: =J39-'Exec.Summary_Liquiplanung ORG'!D38 -> 0 | N39: =März!AH38 -> 0 | O39: 0 | P39: =N39-'Exec.Summary_Liquiplanung ORG'!E38 -> 0 | R39: =April!AH38 -> 0 | S39: 0 | T39: =R39-'Exec.Summary_Liquiplanung ORG'!F38 -> 0 | V39: =Mai!AH38 -> 0 | W39: 0 | X39: =V39-'Exec.Summary_Liquiplanung ORG'!G38 -> 0 | Z39: =Juni!AH38 -> 0 | AA39: 0 | AB39: =Z39-'Exec.Summary_Liquiplanung ORG'!H38 -> 0 | AD39: 0
A40: Besonderheiten | B40: =Dezember24!AH39 -> 0 | C40: 0 | D40: =B40-'Exec.Summary_Liquiplanung ORG'!B39 -> 0 | F40: =Januar!AH39 -> 0 | G40: 0 | H40: =F40-'Exec.Summary_Liquiplanung ORG'!C39 -> 0 | J40: =Februar!AH39 -> 20889.36 | K40: 0 | L40: =J40-'Exec.Summary_Liquiplanung ORG'!D39 -> 20889.36 | N40: =März!AH39 -> 2229727.3 | O40: 0 | P40: =N40-'Exec.Summary_Liquiplanung ORG'!E39 -> 2229727.3 | R40: =April!AH39 -> 0 | S40: 0 | T40: =R40-'Exec.Summary_Liquiplanung ORG'!F39 -> 0 | V40: =Mai!AH39 -> 0 | W40: 0 | X40: =V40-'Exec.Summary_Liquiplanung ORG'!G39 -> 0 | Z40: =Juni!AH39 -> 0 | AA40: 0 | AB40: =Z40-'Exec.Summary_Liquiplanung ORG'!H39 -> 0 | AD40: 0
A41: Kreditkarten | B41: =Dezember24!AH40 -> 475599.89 | C41: 967750 | D41: =B41-'Exec.Summary_Liquiplanung ORG'!B40 -> -492150.11 | F41: =Januar!AH40 -> 3810010.6 | G41: 4370953.1 | H41: =F41-'Exec.Summary_Liquiplanung ORG'!C40 -> -560942.47 | J41: =Februar!AH40 -> 4298434.4 | K41: 3908393.5 | L41: =J41-'Exec.Summary_Liquiplanung ORG'!D40 -> 390040.89 | N41: =März!AH40 -> 4815059.8 | O41: 5226279.4 | P41: =N41-'Exec.Summary_Liquiplanung ORG'!E40 -> -411219.6 | R41: =April!AH40 -> 6380242.7 | S41: 4156379.5 | T41: =R41-'Exec.Summary_Liquiplanung ORG'!F40 -> 2223863.1 | V41: =Mai!AH40 -> 4908414.5 | W41: 5207062.2 | X41: =V41-'Exec.Summary_Liquiplanung ORG'!G40 -> -298647.62 | Z41: =Juni!AH40 -> 5222355.2 | AA41: 5127362.8 | AB41: =Z41-'Exec.Summary_Liquiplanung ORG'!H40 -> 94992.426 | AD41: 307359.76
...

Sheet Exec.Summary_Liquiplanung
A1: Liquiditätsplanung | M1: Abweichung zum originalen Finanzplan | V1: Abweichung zum Finanzplan 04.07.25 | AG1: letztes Reporting
B2: December | C2: January | D2: February | E2: March | F2: April | G2: Mai | H2: June | I2: July | J2: August | K2: September | M2: Dec | N2: January | O2: February | P2: March | Q2: April | R2: Mai | S2: June | T2: Sum | V2: Dec | W2: January | X2: February | Y2: March | Z2: April | AA2: Mai | AB2: June | AC2: July | AD2: August | AE2: Sum | AG2: Dec | AH2: January | AI2: February | AJ2: March | AK2: April | AL2: Mai | AM2: June | AN2: July | AO2: August | AP2: Sum
A4: Opening Balance | B4: =Dezember24!R4 -> 3000000 | C4: =Januar!B4 -> 3442499.7 | D4: =Februar!B4 -> 4095387.8 | E4: =März!B6 -> 4710438.2 | F4: =April!B4 -> 8081456.3 | G4: =Mai!B4 -> 10995169 | H4: =Juni!B4 -> 9104878.3 | I4: =Juli!B4 -> 11225488 | J4: =August!B4 -> 8492524.3 | K4: =September!B4 -> 5940023.1 | M4: =B4-'Exec.Summary_Liquiplanung ORG'!B4 -> 0 | N4: =C4-'Exec.Summary_Liquiplanung ORG'!C4 -> -1318969 | O4: =D4-'Exec.Summary_Liquiplanung ORG'!D4 -> -2019137.4 | P4: =E4-'Exec.Summary_Liquiplanung ORG'!E4 -> -1993950.7 | Q4: =F4-'Exec.Summary_Liquiplanung ORG'!F4 -> 2555643.5 | R4: =G4-'Exec.Summary_Liquiplanung ORG'!G4 -> 6469033.1 | S4: =H4-'Exec.Summary_Liquiplanung ORG'!H4 -> 4846591.4 | V4: =B4-AG4 -> 0 | W4: =C4-AH4 -> 0 | X4: =D4-AI4 -> 0 | Y4: =E4-AJ4 -> -29437.152 | Z4: =F4-AK4 -> 173104.08 | AA4: =G4-AL4 -> 465581.91 | AB4: =H4-AM4 -> -1091568.7 | AC4: =I4-AN4 -> 0.43404664 | AD4: =J4-AO4 -> 495887.2 | AG4: 3000000 | AH4: 3442499.7 | AI4: 4095387.8 | AJ4: 4739875.4 | AK4: 7908352.2 | AL4: 10529587 | AM4: 10196447 | AN4: 11225488 | AO4: 7996637.1
A5: Tagesgeld | B5: =Dezember24!AH5 -> 0 | C5: =Januar!AH5 -> 0 | D5: =Februar!AH5 -> 0 | E5: =März!AH5 -> 0 | F5: =April!AH5 -> 0 | G5: =Mai!AH5 -> 0 | H5: =Juni!AH5 -> 0 | I5: =Juli!AH5 -> 0 | J5: =August!AH5 -> 0 | K5: =September!AH5 -> 0 | M5: =B5-'Exec.Summary_Liquiplanung ORG'!B5 -> 0 | N5: =C5-'Exec.Summary_Liquiplanung ORG'!C5 -> 0 | O5: =D5-'Exec.Summary_Liquiplanung ORG'!D5 -> 0 | P5: =E5-'Exec.Summary_Liquiplanung ORG'!E5 -> 0 | Q5: =F5-'Exec.Summary_Liquiplanung ORG'!F5 -> 0 | R5: =G5-'Exec.Summary_Liquiplanung ORG'!G5 -> 0 | S5: =H5-'Exec.Summary_Liquiplanung ORG'!H5 -> 0 | V5: 0 | W5: 0 | X5: 0 | Y5: 0 | Z5: 0 | AA5: 0 | AB5: 0 | AC5: 0 | AD5: 0 | AG5: 0 | AH5: 0 | AI5: 0 | AJ5: 0 | AK5: 0 | AL5: 0 | AM5: 0 | AN5: 0 | AO5: 0
A6: Summe | B6: =Dezember24!AH6 -> 0 | C6: =Januar!AH6 -> 3442499.7 | D6: =Februar!AH6 -> 4095387.8 | E6: =März!AH6 -> 4710438.2 | F6: =April!AH6 -> 8081456.3 | G6: =Mai!AH6 -> 10995169 | H6: =Juni!AH6 -> 9104878.3 | I6: =Juli!AH6 -> 11225488 | J6: =August!AH6 -> 8492524.3 | K6: =September!AH6 -> 5940023.1 | M6: =B6-'Exec.Summary_Liquiplanung ORG'!B6 -> 0 | N6: =C6-'Exec.Summary_Liquiplanung ORG'!C6 -> -1318969 | O6: =D6-'Exec.Summary_Liquiplanung ORG'!D6 -> -2019137.4 | P6: =E6-'Exec.Summary_Liquiplanung ORG'!E6 -> -1993950.7 | Q6: =F6-'Exec.Summary_Liquiplanung ORG'!F6 -> 2555643.5 | R6: =G6-'Exec.Summary_Liquiplanung ORG'!G6 -> 6469033.1 | S6: =H6-'Exec.Summary_Liquiplanung ORG'!H6 -> 4846591.4 | V6: -1318969 | W6: -3360685.9 | X6: -3301536.4 | Y6: -1284799.1 | Z6: -790866 | AA6: -390733.17 | AB6: 0 | AC6: 0 | AD6: 0 | AG6: 0 | AH6: 3442499.7 | AI6: 4095387.8 | AJ6: 4739875.4 | AK6: 7908352.2 | AL6: 10529587 | AM6: 10196447 | AN6: 11225488 | AO6: 7996637.1
A7: AUSGABEN | G7: =Mai!AH7 | H7: =Juni!AH7 | I7: =Juli!AH7 | J7: =August!AH7 | K7: =September!AH7
A8: Pacht | B8: =Dezember24!AH8 -> 0 | C8: =Januar!AH8 -> 1336978.3 | D8: =Februar!AH8 -> -227726.6 | E8: =März!AH8 -> 1756520.4 | F8: =April!AH8 -> 2715108 | G8: =Mai!AH8 -> 3884517 | H8: =Juni!AH8 -> 0 | I8: =Juli!AH8 -> 1723513 | J8: =August!AH8 -> 1723513 | K8: =September!AH8 -> 1723513 | M8: =B8-'Exec.Summary_Liquiplanung ORG'!B8 -> 0 | N8: =C8-'Exec.Summary_Liquiplanung ORG'!C8 -> -648647.27 | O8: =D8-'Exec.Summary_Liquiplanung ORG'!D8 -> -227726.6 | P8: =E8-'Exec.Summary_Liquiplanung ORG'!E8 -> -399444.71 | Q8: =F8-'Exec.Summary_Liquiplanung ORG'!F8 -> 804841.39 | R8: =G8-'Exec.Summary_Liquiplanung ORG'!G8 -> 1859473.9 | S8: =H8-'Exec.Summary_Liquiplanung ORG'!H8 -> -1910725.9 | T8: =SUM(M8:S8) -> -522229.21 | V8: =B8-AG8 -> 0 | W8: =C8-AH8 -> 0 | X8: =D8-AI8 -> 0 | Y8: =E8-AJ8 -> 0 | Z8: =F8-AK8 -> 0 | AA8: =G8-AL8 -> 0 | AB8: =H8-AM8 -> 0 | AC8: =I8-AN8 -> 0 | AD8: =J8-AO8 -> 0 | AE8: =SUM(V8:AD8) -> 0 | AG8: 0 | AH8: 1336978.3 | AI8: -227726.6 | AJ8: 1756520.4 | AK8: 2715108 | AL8: 3884517 | AM8: 0 | AN8: 1723513 | AO8: 1723513 | AP8: =SUM(AG8:AO8) -> 12912423
A9: Annuität ext. | B9: =Dezember24!AH9 -> 0 | C9: =Januar!AH9 -> 0 | D9: =Februar!AH9 -> 0 | E9: =März!AH9 -> 0 | F9: =April!AH9 -> 0 | G9: =Mai!AH9 -> 0 | H9: =Juni!AH9 -> 0 | I9: =Juli!AH9 -> 0 | J9: =August!AH9 -> 0 | K9: =September!AH9 -> 0 | M9: =B9-'Exec.Summary_Liquiplanung ORG'!B9 -> 0 | N9: =C9-'Exec.Summary_Liquiplanung ORG'!C9 -> 0 | O9: =D9-'Exec.Summary_Liquiplanung ORG'!D9 -> 0 | P9: =E9-'Exec.Summary_Liquiplanung ORG'!E9 -> 0 | Q9: =F9-'Exec.Summary_Liquiplanung ORG'!F9 -> 0 | R9: =G9-'Exec.Summary_Liquiplanung ORG'!G9 -> 0 | S9: =H9-'Exec.Summary_Liquiplanung ORG'!H9 -> 0 | T9: =SUM(M9:S9) -> 0 | V9: =B9-AG9 -> 0 | W9: =C9-AH9 -> 0 | X9: =D9-AI9 -> 0 | Y9: =E9-AJ9 -> 0 | Z9: =F9-AK9 -> 0 | AA9: =G9-AL9 -> 0 | AB9: =H9-AM9 -> 0 | AC9: =I9-AN9 -> 0 | AD9: =J9-AO9 -> 0 | AE9: =SUM(V9:AD9) -> 0 | AG9: 0 | AH9: 0 | AI9: 0 | AJ9: 0 | AK9: 0 | AL9: 0 | AM9: 0 | AN9: 0 | AO9: 0 | AP9: =SUM(AG9:AO9) -> 0
A10: Kreditorenzahlungen | B10: =Dezember24!AH10 -> 65390 | C10: =Januar!AH10 -> 2712411.1 | D10: =Februar!AH10 -> 5020228.1 | E10: =März!AH10 -> 3209571.6 | F10: =April!AH10 -> 1978234.2 | G10: =Mai!AH10 -> 4806305 | H10: =Juni!AH10 -> 5122538.2 | I10: =Juli!AH10 -> 7476262 | J10: =August!AH10 -> 7048256.6 | K10: =September!AH10 -> 6664395.2 | M10: =B10-'Exec.Summary_Liquiplanung ORG'!B10 -> -1184610 | N10: =C10-'Exec.Summary_Liquiplanung ORG'!C10 -> -1337588.9 | O10: =D10-'Exec.Summary_Liquiplanung ORG'!D10 -> -122676.8 | P10: =E10-'Exec.Summary_Liquiplanung ORG'!E10 -> -2887456.6 | Q10: =F10-'Exec.Summary_Liquiplanung ORG'!F10 -> -2848258.9 | R10: =G10-'Exec.Summary_Liquiplanung ORG'!G10 -> -914119.98 | S10: =H10-'Exec.Summary_Liquiplanung ORG'!H10 -> -976595.92 | T10: =SUM(M10:S10) -> -10271307 | V10: =B10-AG10 -> 0 | W10: =C10-AH10 -> 0 | X10: =D10-AI10 -> 0 | Y10: =E10-AJ10 -> 0 | Z10: =F10-AK10 -> 0 | AA10: =G10-AL10 -> 486672.09 | AB10: =H10-AM10 -> -1222670.4 | AC10: =I10-AN10 -> -861381.27 | AD10: =J10-AO10 -> -155637.16 | AE10: =SUM(V10:AD10) -> -1753016.7 | AG10: 65390 | AH10: 2712411.1 | AI10: 5020228.1 | AJ10: 3209571.6 | AK10: 1978234.2 | AL10: 4319632.9 | AM10: 6345208.6 | AN10: 8337643.3 | AO10: 7203893.8 | AP10: =SUM(AG10:AO10) -> 39192213
A11: Aktivbank/Progros | B11: =Dezember24!AH11 -> 0 | C11: =Januar!AH11 -> 80069 | D11: =Februar!AH11 -> 0 | E11: =März!AH11 -> 0 | F11: =April!AH11 -> 0 | G11: =Mai!AH11 -> 0 | H11: =Juni!AH11 -> 0 | I11: =Juli!AH11 -> 0 | J11: =August!AH11 -> 0 | K11: =September!AH11 -> 0 | M11: =B11-'Exec.Summary_Liquiplanung ORG'!B11 -> 0 | N11: =C11-'Exec.Summary_Liquiplanung ORG'!C11 -> 80069 | O11: =D11-'Exec.Summary_Liquiplanung ORG'!D11 -> 0 | P11: =E11-'Exec.Summary_Liquiplanung ORG'!E11 -> 0 | Q11: =F11-'Exec.Summary_Liquiplanung ORG'!F11 -> 0 | R11: =G11-'Exec.Summary_Liquiplanung ORG'!G11 -> 0 | S11: =H11-'Exec.Summary_Liquiplanung ORG'!H11 -> 0 | T11: =SUM(M11:S11) -> 80069 | V11: =B11-AG11 -> 0 | W11: =C11-AH11 -> 0 | X11: =D11-AI11 -> 0 | Y11: =E11-AJ11 -> 0 | Z11: =F11-AK11 -> 0 | AA11: =G11-AL11 -> 0 | AB11: =H11-AM11 -> 0 | AC11: =I11-AN11 -> 0 | AD11: =J11-AO11 -> 0 | AE11: =SUM(V11:AD11) -> 0 | AG11: 0 | AH11: 80069 | AI11: 0 | AJ11: 0 | AK11: 0 | AL11: 0 | AM11: 0 | AN11: 0 | AO11: 0 | AP11: =SUM(AG11:AO11) -> 80069
A12: Lastschriften | B12: =Dezember24!AH12 -> 0 | C12: =Januar!AH12 -> 541051.79 | D12: =Februar!AH12 -> 0 | E12: =März!AH12 -> 0 | F12: =April!AH12 -> 0 | G12: =Mai!AH12 -> 0 | H12: =Juni!AH12 -> 0 | I12: =Juli!AH12 -> 0 | J12: =August!AH12 -> 0 | K12: =September!AH12 -> 0 | M12: =B12-'Exec.Summary_Liquiplanung ORG'!B12 -> 0 | N12: =C12-'Exec.Summary_Liquiplanung ORG'!C12 -> 541051.79 | O12: =D12-'Exec.Summary_Liquiplanung ORG'!D12 -> 0 | P12: =E12-'Exec.Summary_Liquiplanung ORG'!E12 -> 0 | Q12: =F12-'Exec.Summary_Liquiplanung ORG'!F12 -> 0 | R12: =G12-'Exec.Summary_Liquiplanung ORG'!G12 -> 0 | S12: =H12-'Exec.Summary_Liquiplanung ORG'!H12 -> 0 | T12: =SUM(M12:S12) -> 541051.79 | V12: =B12-AG12 -> 0 | W12: =C12-AH12 -> 0 | X12: =D12-AI12 -> 0 | Y12: =E12-AJ12 -> 0 | Z12: =F12-AK12 -> 0 | AA12: =G12-AL12 -> 0 | AB12: =H12-AM12 -> 0 | AC12: =I12-AN12 -> 0 | AD12: =J12-AO12 -> 0 | AE12: =SUM(V12:AD12) -> 0 | AG12: 0 | AH12: 541051.79 | AI12: 0 | AJ12: 0 | AK12: 0 | AL12: 0 | AM12: 0 | AN12: 0 | AO12: 0 | AP12: =SUM(AG12:AO12) -> 541051.79
A13: Energiedienstleister | B13: =Dezember24!AH13 -> 0 | C13: =Januar!AH13 -> 148000 | D13: =Februar!AH13 -> 0 | E13: =März!AH13 -> 0 | F13: =April!AH13 -> 0 | G13: =Mai!AH13 -> 0 | H13: =Juni!AH13 -> 0 | I13: =Juli!AH13 -> 0 | J13: =August!AH13 -> 0 | K13: =September!AH13 -> 0 | M13: =B13-'Exec.Summary_Liquiplanung ORG'!B13 -> 0 | N13: =C13-'Exec.Summary_Liquiplanung ORG'!C13 -> 148000 | O13: =D13-'Exec.Summary_Liquiplanung ORG'!D13 -> 0 | P13: =E13-'Exec.Summary_Liquiplanung ORG'!E13 -> 0 | Q13: =F13-'Exec.Summary_Liquiplanung ORG'!F13 -> 0 | R13: =G13-'Exec.Summary_Liquiplanung ORG'!G13 -> 0 | S13: =H13-'Exec.Summary_Liquiplanung ORG'!H13 -> 0 | T13: =SUM(M13:S13) -> 148000 | V13: =B13-AG13 -> 0 | W13: =C13-AH13 -> 0 | X13: =D13-AI13 -> 0 | Y13: =E13-AJ13 -> 0 | Z13: =F13-AK13 -> 0 | AA13: =G13-AL13 -> 0 | AB13: =H13-AM13 -> 0 | AC13: =I13-AN13 -> 0 | AD13: =J13-AO13 -> 0 | AE13: =SUM(V13:AD13) -> 0 | AG13: 0 | AH13: 148000 | AI13: 0 | AJ13: 0 | AK13: 0 | AL13: 0 | AM13: 0 | AN13: 0 | AO13: 0 | AP13: =SUM(AG13:AO13) -> 148000
A14: Telekommunikation | B14: =Dezember24!AH14 -> 0 | C14: =Januar!AH14 -> 393051.79 | D14: =Februar!AH14 -> 0 | E14: =März!AH14 -> 0 | F14: =April!AH14 -> 0 | G14: =Mai!AH14 -> 0 | H14: =Juni!AH14 -> 0 | I14: =Juli!AH14 -> 0 | J14: =August!AH14 -> 0 | K14: =September!AH14 -> 0 | M14: =B14-'Exec.Summary_Liquiplanung ORG'!B14 -> 0 | N14: =C14-'Exec.Summary_Liquiplanung ORG'!C14 -> 393051.79 | O14: =D14-'Exec.Summary_Liquiplanung ORG'!D14 -> 0 | P14: =E14-'Exec.Summary_Liquiplanung ORG'!E14 -> 0 | Q14: =F14-'Exec.Summary_Liquiplanung ORG'!F14 -> 0 | R14: =G14-'Exec.Summary_Liquiplanung ORG'!G14 -> 0 | S14: =H14-'Exec.Summary_Liquiplanung ORG'!H14 -> 0 | T14: =SUM(M14:S14) -> 393051.79 | V14: =B14-AG14 -> 0 | W14: =C14-AH14 -> 0 | X14: =D14-AI14 -> 0 | Y14: =E14-AJ14 -> 0 | Z14: =F14-AK14 -> 0 | AA14: =G14-AL14 -> 0 | AB14: =H14-AM14 -> 0 | AC14: =I14-AN14 -> 0 | AD14: =J14-AO14 -> 0 | AE14: =SUM(V14:AD14) -> 0 | AG14: 0 | AH14: 393051.79 | AI14: 0 | AJ14: 0 | AK14: 0 | AL14: 0 | AM14: 0 | AN14: 0 | AO14: 0 | AP14: =SUM(AG14:AO14) -> 393051.79
A15: Gebühren CC | B15: =Dezember24!AH15 -> 0 | C15: =Januar!AH15 -> 0 | D15: =Februar!AH15 -> 0 | E15: =März!AH15 -> 0 | F15: =April!AH15 -> 0 | G15: =Mai!AH15 -> 0 | H15: =Juni!AH15 -> 0 | I15: =Juli!AH15 -> 0 | J15: =August!AH15 -> 0 | K15: =September!AH15 -> 0 | M15: =B15-'Exec.Summary_Liquiplanung ORG'!B15 -> 0 | N15: =C15-'Exec.Summary_Liquiplanung ORG'!C15 -> 0 | O15: =D15-'Exec.Summary_Liquiplanung ORG'!D15 -> 0 | P15: =E15-'Exec.Summary_Liquiplanung ORG'!E15 -> 0 | Q15: =F15-'Exec.Summary_Liquiplanung ORG'!F15 -> 0 | R15: =G15-'Exec.Summary_Liquiplanung ORG'!G15 -> 0 | S15: =H15-'Exec.Summary_Liquiplanung ORG'!H15 -> 0 | T15: =SUM(M15:S15) -> 0 | V15: =B15-AG15 -> 0 | W15: =C15-AH15 -> 0 | X15: =D15-AI15 -> 0 | Y15: =E15-AJ15 -> 0 | Z15: =F15-AK15 -> 0 | AA15: =G15-AL15 -> 0 | AB15: =H15-AM15 -> 0 | AC15: =I15-AN15 -> 0 | AD15: =J15-AO15 -> 0 | AE15: =SUM(V15:AD15) -> 0 | AG15: 0 | AH15: 0 | AI15: 0 | AJ15: 0 | AK15: 0 | AL15: 0 | AM15: 0 | AN15: 0 | AO15: 0 | AP15: =SUM(AG15:AO15) -> 0
A16: Provisonen( Booking, Expedia | B16: =Dezember24!AH16 -> 0 | C16: =Januar!AH16 -> 0 | D16: =Februar!AH16 -> 0 | E16: =März!AH16 -> 0 | F16: =April!AH16 -> 0 | G16: =Mai!AH16 -> 0 | H16: =Juni!AH16 -> 0 | I16: =Juli!AH16 -> 0 | J16: =August!AH16 -> 0 | K16: =September!AH16 -> 0 | M16: =B16-'Exec.Summary_Liquiplanung ORG'!B16 -> 0 | N16: =C16-'Exec.Summary_Liquiplanung ORG'!C16 -> 0 | O16: =D16-'Exec.Summary_Liquiplanung ORG'!D16 -> 0 | P16: =E16-'Exec.Summary_Liquiplanung ORG'!E16 -> 0 | Q16: =F16-'Exec.Summary_Liquiplanung ORG'!F16 -> 0 | R16: =G16-'Exec.Summary_Liquiplanung ORG'!G16 -> 0 | S16: =H16-'Exec.Summary_Liquiplanung ORG'!H16 -> 0 | T16: =SUM(M16:S16) -> 0 | V16: =B16-AG16 -> 0 | W16: =C16-AH16 -> 0 | X16: =D16-AI16 -> 0 | Y16: =E16-AJ16 -> 0 | Z16: =F16-AK16 -> 0 | AA16: =G16-AL16 -> 0 | AB16: =H16-AM16 -> 0 | AC16: =I16-AN16 -> 0 | AD16: =J16-AO16 -> 0 | AE16: =SUM(V16:AD16) -> 0 | AG16: 0 | AH16: 0 | AI16: 0 | AJ16: 0 | AK16: 0 | AL16: 0 | AM16: 0 | AN16: 0 | AO16: 0 | AP16: =SUM(AG16:AO16) -> 0
A17: KFZ Leasing | B17: =Dezember24!AH17 -> 0 | C17: =Januar!AH17 -> 0 | D17: =Februar!AH17 -> 0 | E17: =März!AH17 -> 0 | F17: =April!AH17 -> 0 | G17: =Mai!AH17 -> 0 | H17: =Juni!AH17 -> 0 | I17: =Juli!AH17 -> 0 | J17: =August!AH17 -> 0 | K17: =September!AH17 -> 0 | M17: =B17-'Exec.Summary_Liquiplanung ORG'!B17 -> 0 | N17: =C17-'Exec.Summary_Liquiplanung ORG'!C17 -> 0 | O17: =D17-'Exec.Summary_Liquiplanung ORG'!D17 -> 0 | P17: =E17-'Exec.Summary_Liquiplanung ORG'!E17 -> 0 | Q17: =F17-'Exec.Summary_Liquiplanung ORG'!F17 -> 0 | R17: =G17-'Exec.Summary_Liquiplanung ORG'!G17 -> 0 | S17: =H17-'Exec.Summary_Liquiplanung ORG'!H17 -> 0 | T17: =SUM(M17:S17) -> 0 | V17: =B17-AG17 -> 0 | W17: =C17-AH17 -> 0 | X17: =D17-AI17 -> 0 | Y17: =E17-AJ17 -> 0 | Z17: =F17-AK17 -> 0 | AA17: =G17-AL17 -> 0 | AB17: =H17-AM17 -> 0 | AC17: =I17-AN17 -> 0 | AD17: =J17-AO17 -> 0 | AE17: =SUM(V17:AD17) -> 0 | AG17: 0 | AH17: 0 | AI17: 0 | AJ17: 0 | AK17: 0 | AL17: 0 | AM17: 0 | AN17: 0 | AO17: 0 | AP17: =SUM(AG17:AO17) -> 0
A18: Jobtickets | B18: =Dezember24!AH18 -> 0 | C18: =Januar!AH18 -> 0 | D18: =Februar!AH18 -> 0 | E18: =März!AH18 -> 0 | F18: =April!AH18 -> 0 | G18: =Mai!AH18 -> 0 | H18: =Juni!AH18 -> 0 | I18: =Juli!AH18 -> 0 | J18: =August!AH18 -> 0 | K18: =September!AH18 -> 0 | M18: =B18-'Exec.Summary_Liquiplanung ORG'!B18 -> 0 | N18: =C18-'Exec.Summary_Liquiplanung ORG'!C18 -> 0 | O18: =D18-'Exec.Summary_Liquiplanung ORG'!D18 -> 0 | P18: =E18-'Exec.Summary_Liquiplanung ORG'!E18 -> 0 | Q18: =F18-'Exec.Summary_Liquiplanung ORG'!F18 -> 0 | R18: =G18-'Exec.Summary_Liquiplanung ORG'!G18 -> 0 | S18: =H18-'Exec.Summary_Liquiplanung ORG'!H18 -> 0 | T18: =SUM(M18:S18) -> 0 | V18: =B18-AG18 -> 0 | W18: =C18-AH18 -> 0 | X18: =D18-AI18 -> 0 | Y18: =E18-AJ18 -> 0 | Z18: =F18-AK18 -> 0 | AA18: =G18-AL18 -> 0 | AB18: =H18-AM18 -> 0 | AC18: =I18-AN18 -> 0 | AD18: =J18-AO18 -> 0 | AE18: =SUM(V18:AD18) -> 0 | AG18: 0 | AH18: 0 | AI18: 0 | AJ18: 0 | AK18: 0 | AL18: 0 | AM18: 0 | AN18: 0 | AO18: 0 | AP18: =SUM(AG18:AO18) -> 0
A19: Leasing | B19: =Dezember24!AH19 -> 0 | C19: =Januar!AH19 -> 0 | D19: =Februar!AH19 -> 0 | E19: =März!AH19 -> 0 | F19: =April!AH19 -> 0 | G19: =Mai!AH19 -> 0 | H19: =Juni!AH19 -> 0 | I19: =Juli!AH19 -> 0 | J19: =August!AH19 -> 0 | K19: =September!AH19 -> 0 | M19: =B19-'Exec.Summary_Liquiplanung ORG'!B19 -> 0 | N19: =C19-'Exec.Summary_Liquiplanung ORG'!C19 -> 0 | O19: =D19-'Exec.Summary_Liquiplanung ORG'!D19 -> 0 | P19: =E19-'Exec.Summary_Liquiplanung ORG'!E19 -> 0 | Q19: =F19-'Exec.Summary_Liquiplanung ORG'!F19 -> 0 | R19: =G19-'Exec.Summary_Liquiplanung ORG'!G19 -> 0 | S19: =H19-'Exec.Summary_Liquiplanung ORG'!H19 -> 0 | T19: =SUM(M19:S19) -> 0 | V19: =B19-AG19 -> 0 | W19: =C19-AH19 -> 0 | X19: =D19-AI19 -> 0 | Y19: =E19-AJ19 -> 0 | Z19: =F19-AK19 -> 0 | AA19: =G19-AL19 -> 0 | AB19: =H19-AM19 -> 0 | AC19: =I19-AN19 -> 0 | AD19: =J19-AO19 -> 0 | AE19: =SUM(V19:AD19) -> 0 | AG19: 0 | AH19: 0 | AI19: 0 | AJ19: 0 | AK19: 0 | AL19: 0 | AM19: 0 | AN19: 0 | AO19: 0 | AP19: =SUM(AG19:AO19) -> 0
... A30: Berater-/ Verfahrenskosten Insolvenzverfahren | B30: =Dezember24!AH30 -> 0 | C30: =Januar!AH30 -> 0 | D30: =Februar!AH30 -> 1500000 | E30: =März!AH30 -> 0 | F30: =April!AH30 -> 0 | G30: =Mai!AH30 -> 0 | H30: =Juni!AH30 -> 0 | I30: =Juli!AH30 -> 0 | J30: =August!AH30 -> 0 | K30: =September!AH30 -> 2400000 | M30: =B30-'Exec.Summary_Liquiplanung ORG'!B30 -> 0 | N30: =C30-'Exec.Summary_Liquiplanung ORG'!C30 -> 0 | O30: =D30-'Exec.Summary_Liquiplanung ORG'!D30 -> 0 | P30: =E30-'Exec.Summary_Liquiplanung ORG'!E30 -> 0 | Q30: =F30-'Exec.Summary_Liquiplanung ORG'!F30 -> 0 | R30: =G30-'Exec.Summary_Liquiplanung ORG'!G30 -> 0 | S30: =H30-'Exec.Summary_Liquiplanung ORG'!H30 -> -2400000 | T30: =SUM(M30:S30) -> -2400000 | V30: =B30-AG30 -> 0 | W30: =C30-AH30 -> 0 | X30: =D30-AI30 -> 0 | Y30: =E30-AJ30 -> 0 | Z30: =F30-AK30 -> 0 | AA30: =G30-AL30 -> 0 | AB30: =H30-AM30 -> 0 | AC30: =I30-AN30 -> 0 | AD30: =J30-AO30 -> -2400000 | AE30: =SUM(V30:AD30) -> -2400000 | AG30: 0 | AH30: 0 | AI30: 1500000 | AJ30: 0 | AK30: 0 | AL30: 0 | AM30: 0 | AN30: 0 | AO30: 2400000 | AP30: =SUM(AG30:AO30) -> 3900000
A31: div. Abbuchungen | B31: =Dezember24!AH31 -> 0 | C31: =Januar!AH31 -> 0 | D31: =Februar!AH31 -> 98500 | E31: =März!AH31 -> 0 | F31: =April!AH31 -> 0 | G31: =Mai!AH31 -> 0 | H31: =Juni!AH31 -> 0 | I31: =Juli!AH31 -> 0 | J31: =August!AH31 -> 0 | K31: =September!AH31 -> 0 | M31: =B31-'Exec.Summary_Liquiplanung ORG'!B31 -> 0 | N31: =C31-'Exec.Summary_Liquiplanung ORG'!C31 -> 0 | O31: =D31-'Exec.Summary_Liquiplanung ORG'!D31 -> 98500 | P31: =E31-'Exec.Summary_Liquiplanung ORG'!E31 -> 0 | Q31: =F31-'Exec.Summary_Liquiplanung ORG'!F31 -> 0 | R31: =G31-'Exec.Summary_Liquiplanung ORG'!G31 -> 0 | S31: =H31-'Exec.Summary_Liquiplanung ORG'!H31 -> 0 | T31: =SUM(M31:S31) -> 98500 | V31: 0 | W31: 0 | X31: 0 | Y31: 0 | Z31: 0 | AA31: 0 | AB31: 0 | AC31: 0 | AD31: 0 | AE31: 0 | AG31: 0 | AH31: 0 | AI31: 98500 | AJ31: 0 | AK31: 0 | AL31: 0 | AM31: 0 | AN31: 0 | AO31: 0 | AP31: 0
A32: Summe Ausgaben | B32: =Dezember24!AH32 -> 65390 | C32: =Januar!AH32 -> 4712650.2 | D32: =Februar!AH32 -> 6561001.5 | E32: =März!AH32 -> 7811988.6 | F32: =April!AH32 -> 7859457.2 | G32: =Mai!AH32 -> 11915822 | H32: =Juni!AH32 -> 8022538.2 | I32: =Juli!AH32 -> 12099775 | J32: =August!AH32 -> 11671770 | K32: =September!AH32 -> 13687908 | M32: =B32-'Exec.Summary_Liquiplanung ORG'!B32 -> -1354610 | N32: =C32-'Exec.Summary_Liquiplanung ORG'!C32 -> -1482660.4 | O32: =D32-'Exec.Summary_Liquiplanung ORG'!D32 -> -288338.33 | P32: =E32-'Exec.Summary_Liquiplanung ORG'!E32 -> -3033905.8 | Q32: =F32-'Exec.Summary_Liquiplanung ORG'!F32 -> -1658471.4 | R32: =G32-'Exec.Summary_Liquiplanung ORG'!G32 -> 1491699.7 | S32: =H32-'Exec.Summary_Liquiplanung ORG'!H32 -> -4941258.4 | T32: =SUM(M32:S32) -> -11267545 | V32: =SUM(V8:V30) -> 0 | W32: =SUM(W8:W30) -> 0 | X32: =SUM(X8:X30) -> 0 | Y32: =SUM(Y8:Y30) -> 0 | Z32: =SUM(Z8:Z30) -> 0 | AA32: =SUM(AA8:AA30) -> 486672.09 | AB32: =SUM(AB8:AB30) -> -1222670.4 | AC32: =SUM(AC8:AC30) -> -861381.27 | AD32: =SUM(AD8:AD30) -> -2555637.2 | AE32: =SUM(V32:AD32) -> -4153016.7 | AG32: 65390 | AH32: 4712650.2 | AI32: 6561001.5 | AJ32: 7811988.6 | AK32: 7859457.2 | AL32: 11429150 | AM32: 9245208.6 | AN32: 12961156 | AO32: 14227407 | AP32: =SUM(AG32:AO32) -> 74873409
M33: =B33-'Exec.Summary_Liquiplanung ORG'!B33 -> 0 | N33: =C33-'Exec.Summary_Liquiplanung ORG'!C33 -> 0 | O33: =D33-'Exec.Summary_Liquiplanung ORG'!D33 -> 0 | P33: =E33-'Exec.Summary_Liquiplanung ORG'!E33 -> 0 | Q33: =F33-'Exec.Summary_Liquiplanung ORG'!F33 -> 0 | R33: =G33-'Exec.Summary_Liquiplanung ORG'!G33 -> 0 | S33: =H33-'Exec.Summary_Liquiplanung ORG'!H33 -> 0 | T33: =SUM(M33:S33) -> 0
A34: EINNAHMEN
A35: Vorauszahlungen | B35: =Dezember24!AH35 -> 0 | C35: =Januar!AH35 -> 0 | D35: =Februar!AH35 -> 0 | E35: =März!AH35 -> 0 | F35: =April!AH35 -> 0 | G35: =Mai!AH35 -> 0 | H35: =Juni!AH35 -> 0 | I35: =Juli!AH35 -> 0 | J35: =August!AH35 -> 0 | K35: =September!AH35 -> 0 | M35: =B35-'Exec.Summary_Liquiplanung ORG'!B35 -> 0 | N35: =C35-'Exec.Summary_Liquiplanung ORG'!C35 -> 0 | O35: =D35-'Exec.Summary_Liquiplanung ORG'!D35 -> 0 | P35: =E35-'Exec.Summary_Liquiplanung ORG'!E35 -> 0 | Q35: =F35-'Exec.Summary_Liquiplanung ORG'!F35 -> 0 | R35: =G35-'Exec.Summary_Liquiplanung ORG'!G35 -> 0 | S35: =H35-'Exec.Summary_Liquiplanung ORG'!H35 -> 0 | T35: =SUM(M35:S35) -> 0 | V35: 0 | W35: 0 | X35: 0 | Y35: 0 | Z35: 0 | AA35: 0 | AB35: 0 | AC35: 0 | AD35: 0 | AE35: 0 | AG35: 0 | AH35: 0 | AI35: 0 | AJ35: 0 | AK35: 0 | AL35: 0 | AM35: 0 | AN35: 0 | AO35: 0 | AP35: 0
