Workbook

Sheet PLAN Zahlen
C2: Liquidität: PLAN
C4: Firma: | F4: 2022 | K4: 2023 | W4: 2024
C5: Stichtag:
C7: Wochendende | F7: August | G7: September | H7: Oktober | I7: November | J7: Dezember | K7: Januar | L7: Februar | M7: März | N7: April | O7: Mai | P7: Juni | Q7: Juli | R7: August | S7: September | T7: Oktober | U7: November | V7: Dezember | W7: Januar | X7: Februar | Y7: März | Z7: April | AA7: Mai | AB7: Juni | AC7: Juli | AD7: August
C9: Anfangsbestand | F9: =E62 -> 0 | G9: =F62 -> 1334.92 | H9: =G62 -> 3941.92 | I9: =H62 -> 6282.92 | J9: =I62 -> 8623.92 | K9: =J62 -> 10964.92 | L9: =K62 -> 11855.92 | M9: =L62 -> 12746.92 | ... AG9: =AF62 -> 58400.92
B11: 1. | C11: Zahlungseingänge
B13: 1.1. | C13: Neukunden (Leistung ab Insolvenzantrag)
C14: Kundeneinzahlungen | E14: 0
C15: Factoring | E15: 0
C16: Factoring (Sicherungseinbehalt) | E16: 0
B17: 1.2. | C17: Altkunden (Leistung vor Insolvenzantrag) | E17: 0 | F17: 24130.84 | G17: 26000 | H17: 32000 | I17: 32000 | J17: 32000 | K17: 32000 | L17: 32000 | M17: 32000 | N17: 32000 | O17: 32000 | P17: 32000 | Q17: 32000 | R17: 32000 | S17: 32000 | T17: 32000 | U17: 32000 | V17: 32000 | W17: 37000 | X17: 37000 | Y17: 37000 | Z17: 37000 | AA17: 37000 | AB17: 37000 | AC17: 37000 | AD17: 37000
B18: 1.3. | C18: Sonstige Eingänge | E18: 0
B19: 1.4. | E19: 0
E20: 0
E21: 0
E22: 0
E23: 0
E24: 0
E25: 0
C27: Summe Zahlungseingänge | F27: =SUM(F13:F26) -> 24130.84 | G27: =SUM(G13:G26) -> 26000 | H27: =SUM(H13:H26) -> 32000 | I27: =SUM(I13:I26) -> 32000 | J27: =SUM(J13:J26) -> 32000 | K27: =SUM(K13:K26) -> 32000 | L27: =SUM(L13:L26) -> 32000 | M27: =SUM(M13:M26) -> 32000 | ... AG27: =SUM(AG13:AG26) -> 0
B29: 2. | C29: Zahlungsausgänge
B31: 2.1. | C31: Materialkosten | E31: 0
B32: 2.2. | C32: Löhne und Gehälter
C33: Löhne | E33: 0
C34: Gehälter | E34: 0 | F34: =- 2000 + - 1600 -> -3600 | G34: =- 1600 + - 2000 -> -3600 | H34: =- 2000 + - 1800 + - 1800 -> -5600 | I34: =- 2000 + - 1800 + - 1800 -> -5600 | J34: =- 2000 + - 1800 + - 1800 -> -5600 | K34: =- 2000 + - 1800 + - 1800 -> -5600 | L34: =- 2000 + - 1800 + - 1800 -> -5600 | M34: =- 2000 + - 1800 + - 1800 -> -5600 | N34: =- 2000 + - 1800 + - 1800 -> -5600 | O34: =- 2000 + - 1800 + - 1800 -> -5600 | ... AD34: =- 2000 + - 1800 + - 1800 -> -5600
C35: Sozialversicherung | E35: 0 | F35: =- 2249.24 + - 648.3 + - 283 -> -3180.54 | G35: =- 1500 + - 642 -> -2142 | H35: -2400 | I35: -2400 | J35: -2400 | K35: -2400 | L35: -2400 | M35: -2400 | N35: -2400 | O35: -2400 | P35: -2400 | Q35: -2400 | R35: -2400 | S35: -2400 | T35: -2400 | U35: -2400 | V35: -2400 | W35: -2400 | X35: -2400 | Y35: -2400 | Z35: -2400 | AA35: -2400 | AB35: -2400 | AC35: -2400 | AD35: -2400
C36: Lohnsteuer | E36: 0 | F36: -250 | G36: -250 | H36: -300 | I36: -300 | J36: -300 | K36: -300 | L36: -300 | M36: -300 | N36: -300 | O36: -300 | P36: -300 | Q36: -300 | R36: -300 | S36: -300 | T36: -300 | U36: -300 | V36: -300 | W36: -300 | X36: -300 | Y36: -300 | Z36: -300 | AA36: -300 | AB36: -300 | AC36: -300 | AD36: -300
C37: Sonstiges | E37: 0
C38: Gesamtsumme | E38: =SUM(E39:E43) -> 0 | F38: =SUM(F33:F37) -> -7030.54 | G38: =SUM(G33:G37) -> -5992 | R38: =SUM(R33:R37) -> -8300 | S38: =SUM(S33:S37) -> -8300 | T38: =SUM(T33:T37) -> -8300 | U38: =SUM(U33:U37) -> -8300 | V38: =SUM(V33:V37) -> -8300 | W38: =SUM(W33:W37) -> -8300 | X38: =SUM(X33:X37) -> -8300 | Y38: =SUM(Y33:Y37) -> -8300 | ... AG38: =SUM(AG33:AG37) -> 0
B39: 2.3. | C39: Umsatzsteuer | E39: 0 | F39: -3853 | G39: -4151 | H39: -5109 | I39: -5109 | J39: -5109 | K39: -5109 | L39: -5109 | M39: -5109 | N39: -5109 | O39: -5109 | P39: -5109 | Q39: -5109 | R39: -5109 | S39: -5109 | T39: -5109 | U39: -5109 | V39: -5109 | W39: -5907 | X39: -5907 | Y39: -5907 | Z39: -5907 | AA39: -5907 | AB39: -5907 | AC39: -5907 | AD39: -5907
B40: 2.4. | C40: Strom/Gas | E40: 0 | F40: -500 | G40: -500 | H40: -500 | I40: -500 | J40: -500 | K40: -500 | L40: -500 | M40: -500 | N40: -500 | O40: -500 | P40: -500 | Q40: -500 | R40: -500 | S40: -500 | T40: -500 | U40: -500 | V40: -500 | W40: -500 | X40: -500 | Y40: -500 | Z40: -500 | AA40: -500 | AB40: -500 | AC40: -500 | AD40: -500
B41: 2.5. | C41: Lease/Miete/Tilgung (Fuhrpark) | E41: 0 | F41: =- 1330.41 + - 367.48 + - 500 + - 408.89 -> -2606.78 | G41: -3000 | H41: -5000 | I41: -5000 | J41: -5000 | K41: -5000 | L41: -5000 | M41: -5000 | N41: -5000 | O41: -5000 | P41: -5000 | Q41: -5000 | R41: -5000 | S41: -5000 | T41: -5000 | U41: -5000 | V41: -5000 | W41: -5000 | X41: -5000 | Y41: -5000 | Z41: -5000 | AA41: -5000 | AB41: -5000 | AC41: -5000 | AD41: -5000
B42: 2.5. | C42: Kraftstoff | E42: 0 | F42: -2500 | G42: -2500 | H42: -3500 | I42: -3500 | J42: -3500 | K42: -3500 | L42: -3500 | M42: -3500 | N42: -3500 | O42: -3500 | P42: -3500 | Q42: -3500 | R42: -3500 | S42: -3500 | T42: -3500 | U42: -3500 | V42: -3500 | W42: -3500 | X42: -3500 | Y42: -3500 | Z42: -3500 | AA42: -3500 | AB42: -3500 | AC42: -3500 | AD42: -3500
B43: 2.6. | C43: Miete Geschäftsräume | E43: 0 | F43: -392 | G43: -500 | H43: -500 | I43: -500 | J43: -500 | K43: -500 | L43: -500 | M43: -500 | N43: -500 | O43: -500 | P43: -500 | Q43: -500 | R43: -500 | S43: -500 | T43: -500 | U43: -500 | V43: -500 | W43: -500 | X43: -500 | Y43: -500 | Z43: -500 | AA43: -500 | AB43: -500 | AC43: -500 | AD43: -500
B44: 2.7. | C44: Rückzahlung Darlehen | E44: 0 | K44: -1000 | L44: -1000 | M44: -1000 | N44: -1000 | O44: -1000 | P44: -1000 | Q44: -1000 | R44: -1000 | S44: -1000 | T44: -1000 | U44: -1000 | V44: -1000 | W44: -1000 | X44: -1000 | Y44: -1000 | Z44: -1000 | AA44: -1000 | AB44: -1000 | AC44: -1000 | AD44: -1000
B45: 2.8. | C45: Versicherungen | E45: 0 | F45: =- 1500 + - 163.6 -> -1663.6 | G45: -2500 | H45: -2500 | I45: -2500 | J45: -2500 | K45: -2500 | L45: -2500 | M45: -2500 | N45: -2500 | O45: -2500 | P45: -2500 | Q45: -2500 | R45: -2500 | S45: -2500 | T45: -2500 | U45: -2500 | V45: -2500 | W45: -2500 | X45: -2500 | Y45: -2500 | Z45: -2500 | AA45: -2500 | AB45: -2500 | AC45: -2500 | AD45: -2500
B46: 2.9. | C46: Sonstige Dauerschuldverhältnisse | E46: 0
B47: 2.10. | C47: Beratungskosten | E47: 0 | F47: -700 | G47: -700 | H47: -700 | I47: -700 | J47: -700 | K47: -700 | L47: -700 | M47: -700 | N47: -700 | O47: -700 | P47: -700 | Q47: -700 | R47: -700 | S47: -700 | T47: -700 | U47: -700 | V47: -700 | W47: -700 | X47: -700 | Y47: -700 | Z47: -700 | AA47: -700 | AB47: -700 | AC47: -700 | AD47: -700
B48: 2.11. | C48: Reparaturen Kfz | E48: 0 | F48: -250 | G48: -250 | H48: -250 | I48: -250 | J48: -250 | K48: -700 | L48: -700 | M48: -700 | N48: -700 | O48: -700 | P48: -700 | Q48: -700 | R48: -700 | S48: -700 | T48: -700 | U48: -700 | V48: -700 | W48: -700 | X48: -700 | Y48: -700 | Z48: -700 | AA48: -700 | AB48: -700 | AC48: -700 | AD48: -700
B49: 2.12. | C49: Zinsen/Gebühren (z.B. InsoGeld) | E49: 0 | F49: -300 | G49: -300 | H49: -300 | I49: -300 | J49: -300 | K49: -300 | L49: -300 | M49: -300 | N49: -300 | O49: -300 | P49: -300 | Q49: -300 | R49: -300 | S49: -300 | T49: -300 | U49: -300 | V49: -300 | W49: -300 | X49: -300 | Y49: -300 | Z49: -300 | AA49: -300 | AB49: -300 | AC49: -300 | AD49: -300
...

Sheet IST Zahlen
B2: Liquidität: IST | K2: 2021 | W2: 2022
E4: INSOLVENZ-
E5: ANTRAG | F5: ='PLAN Zahlen'!F7 -> August | G5: ='PLAN Zahlen'!G7 -> September | H5: ='PLAN Zahlen'!H7 -> Oktober | I5: ='PLAN Zahlen'!I7 -> November | J5: ='PLAN Zahlen'!J7 -> Dezember | K5: ='PLAN Zahlen'!K7 -> Januar | L5: ='PLAN Zahlen'!L7 -> Februar | M5: ='PLAN Zahlen'!M7 -> März | ... AD5: ='PLAN Zahlen'!AD7 -> August | AF5: ='PLAN Zahlen'!AF7 -> 0 | AG5: ='PLAN Zahlen'!AG7 -> 0
C7: Anfangsbestand | E7: ='PLAN Zahlen'!E9 -> 0 | F7: =E60 -> 0 | G7: =F60 -> 0 | H7: =G60 -> 0 | I7: =H60 -> 0 | J7: =I60 -> 0 | K7: =J60 -> 0 | L7: =K60 -> 0 | M7: =L60 -> 0 | ... AG7: =AF60 -> 12775.65
B9: 1. | C9: Zahlungseingänge
B11: ='PLAN Zahlen'!B13 -> 1.1. | C11: ='PLAN Zahlen'!C13 -> Neukunden (Leistung ab Insolvenzantrag) | P11: 447.44
B12: ='PLAN Zahlen'!B14 -> 0 | C12: ='PLAN Zahlen'!C14 -> Kundeneinzahlungen | E12: 0
B13: ='PLAN Zahlen'!B15 -> 0 | C13: ='PLAN Zahlen'!C15 -> Factoring | E13: 0
B14: ='PLAN Zahlen'!B16 -> 0 | C14: ='PLAN Zahlen'!C16 -> Factoring (Sicherungseinbehalt) | E14: 0
B15: ='PLAN Zahlen'!B17 -> 1.2. | C15: ='PLAN Zahlen'!C17 -> Altkunden (Leistung vor Insolvenzantrag) | E15: 0 | F15: 0 | G15: 0 | H15: 0 | I15: 0 | J15: 0 | K15: 0 | L15: 0 | M15: - | N15: 0 | P15: - | Q15: 11667.96 | R15: 15167.2 | S15: =15762+1999 -> 17761 | T15: =25013+1401 -> 26414 | U15: 28784.32 | V15: 24605 | W15: =6471+16340 -> 22811 | X15: =6286+11086 -> 17372 | Y15: 20495 | Z15: 22877 | AA15: 13093 | AB15: 24465 | AC15: 21400 | AD15: 24130.84
B16: ='PLAN Zahlen'!B18 -> 1.3. | C16: ='PLAN Zahlen'!C18 -> Sonstige Eingänge | E16: 0 | O16: 412.2 | V16: 333 | W16: 2380 | Y16: 7500 | AB16: =376+45+31+50+32 -> 534 | AC16: 1030 | AD16: 4.44
B17: ='PLAN Zahlen'!B19 -> 1.4. | C17: Albakour Einzahlungen | E17: 0 | M17: 2400 | N17: 21000 | P17: 7000 | Q17: =2000 + 1000 +350 +50 + 100 + 500 + 3000 -> 7000 | R17: 790 | S17: =500 + 150 + 200 + 3000 -> 3850 | T17: 4700 | V17: 500 | W17: 377 | X17: 1300 | AA17: 1210 | AB17: 2000 | AC17: 80
B18: 1.5. | C18: erhaltene Darlehen | E18: 0 | R18: =3000 + 5000 + 9000 -> 17000 | S18: 3000 | T18: 6000 | U18: 3000
B19: 1.6 | C19: Erst. Ust | E19: 0 | M19: 24 | P19: 822 | R19: 7552 | V19: 5986 | W19: 308 | X19: 3046
B20: 1.7 | C20: Erst. LSt | E20: 0 | T20: =431+144 -> 575
B21: ='PLAN Zahlen'!B23 -> 0 | C21: Rückbuchungen | E21: 0 | R21: 2782 | S21: =210+2511+35+142+15+1380+15 -> 4308 | T21: =2514+1237+167+500 -> 4418 | U21: =500+463+4288+4518+1212+1767+15+15+15+15+15+15+123+65+334 -> 13360 | V21: 1767 | W21: 19707 | X21: 4093 | Y21: 5656 | Z21: 6980 | AA21: 795 | AC21: 750
B22: ='PLAN Zahlen'!B24 -> 0 | C22: ='PLAN Zahlen'!C24 -> 0 | E22: 0
B23: ='PLAN Zahlen'!B25 -> 0 | C23: ='PLAN Zahlen'!C25 -> 0 | E23: 0
C25: Summe Zahlungseingänge | F25: =SUM(F11:F24) -> 0 | G25: =SUM(G11:G24) -> 0 | H25: =SUM(H11:H24) -> 0 | I25: =SUM(I11:I24) -> 0 | J25: =SUM(J11:J24) -> 0 | K25: =SUM(K11:K24) -> 0 | L25: =SUM(L11:L24) -> 0 | M25: =SUM(M11:M24) -> 2424 | ... AG25: =SUM(AG11:AG24) -> 0
B27: ='PLAN Zahlen'!B29 -> 2. | C27: Zahlungsausgänge
B29: ='PLAN Zahlen'!B31 -> 2.1. | C29: ='PLAN Zahlen'!C31 -> Materialkosten | E29: 0 | F29: 0 | G29: 0 | H29: 0 | I29: 0 | J29: 0 | K29: 0 | L29: 0 | M29: 0 | N29: 0
B30: ='PLAN Zahlen'!B32 -> 2.2. | C30: ='PLAN Zahlen'!C32 -> Löhne und Gehälter | F30: 0 | G30: 0 | H30: 0 | I30: 0 | J30: 0 | K30: 0 | L30: 0 | M30: 0
B31: ='PLAN Zahlen'!B33 -> 0 | C31: ='PLAN Zahlen'!C33 -> Löhne | E31: 0 | F31: 0 | G31: 0 | H31: 0 | I31: 0 | J31: 0 | K31: 0 | L31: 0 | M31: 0
B32: ='PLAN Zahlen'!B34 -> 0 | C32: ='PLAN Zahlen'!C34 -> Gehälter | E32: 0 | F32: 0 | G32: 0 | H32: 0 | I32: 0 | J32: 0 | K32: 0 | L32: 0 | M32: 0 | N32: -1376.89 | O32: -1376.89 | P32: -1376.89 | Q32: -1376.89 | R32: =- 1376.89 + - 1653.68 + - 1302.8 + - 871.95 + - 648.6 -> -5853.92 | S32: =- 1653.68 + - 871.95 +- 648.6 + - 1924.01 -> -5098.24 | T32: =- 1653.68 + - 871.95 + - 600 -> -3125.63 | U32: -4802 | V32: -5600 | W32: -1000 | X32: -3400 | Y32: -5409 | Z32: -4400 | AA32: -2400 | AD32: =- 2000 + - 1600 -> -3600
B33: ='PLAN Zahlen'!B35 -> 0 | C33: ='PLAN Zahlen'!C35 -> Sozialversicherung | E33: 0 | F33: 0 | G33: 0 | H33: 0 | I33: 0 | J33: 0 | K33: 0 | L33: 0 | M33: 0 | N33: -822.14 | O33: -1644 | P33: -822.14 | Q33: -822.14 | S33: =- 1603.38 + - 842.46 + - 649.56 -> -3095.4 | AB33: =- 1454.06 + - 1015.12 + - 2632.7 -> -5101.88 | AC33: =-7815-100 -> -7915 | AD33: =- 2249.24 + - 648.3 + - 283 -> -3180.54
B34: ='PLAN Zahlen'!B36 -> 0 | C34: ='PLAN Zahlen'!C36 -> Lohnsteuer | E34: 0 | F34: 0 | G34: 0 | H34: 0 | I34: 0 | J34: 0 | K34: 0 | L34: 0 | M34: 0 | N34: -143.58 | O34: -143.58 | P34: -143.58 | Q34: -143.58 | R34: -430.74 | S34: -144.58
B35: ='PLAN Zahlen'!B37 -> 0 | C35: ='PLAN Zahlen'!C37 -> Sonstiges | E35: 0 | F35: 0 | G35: 0 | H35: 0 | I35: 0 | J35: 0 | K35: 0 | L35: 0 | M35: 0 | N35: 0
B36: ='PLAN Zahlen'!B38 -> 0 | C36: ='PLAN Zahlen'!C38 -> Gesamtsumme | E36: =SUM(E37:E41) -> 0 | F36: 0 | G36: 0 | H36: 0 | I36: 0 | J36: 0 | K36: 0 | L36: 0 | M36: 0 | N36: 0 | Y36: =SUM(Y31:Y35) -> -5409 | Z36: =SUM(Z31:Z35) -> -4400 | AA36: =SUM(AA31:AA35) -> -2400 | AB36: =SUM(AB31:AB35) -> -5101.88 | AC36: =SUM(AC31:AC35) -> -7915 | AD36: =SUM(AD31:AD35) -> -6780.54 | AE36: =SUM(AE31:AE35) -> 0 | AF36: =SUM(AF31:AF35) -> 0 | AG36: =SUM(AG31:AG35) -> 0
B37: ='PLAN Zahlen'!B39 -> 2.3. | C37: ='PLAN Zahlen'!C39 -> Umsatzsteuer | E37: 0 | F37: 0 | G37: 0 | H37: 0 | I37: 0 | J37: 0 | K37: 0 | L37: 0 | M37: 0 | N37: 0
B38: ='PLAN Zahlen'!B40 -> 2.4. | C38: ='PLAN Zahlen'!C40 -> Strom/Gas | E38: 0 | F38: 0 | G38: 0 | H38: 0 | I38: 0 | J38: 0 | K38: 0 | L38: 0 | M38: 0 | N38: 0
B39: ='PLAN Zahlen'!B41 -> 2.5. | C39: ='PLAN Zahlen'!C41 -> Lease/Miete/Tilgung (Fuhrpark) | E39: 0 | F39: 0 | G39: 0 | H39: 0 | I39: 0 | J39: 0 | K39: 0 | L39: 0 | M39: 0 | O39: -404.6 | P39: -1414 | Q39: -1827 | R39: -4096 | S39: =-1526-421-318-2510-3217 -> -7992 | T39: =- 3180.87 + - 1237.6 + - 15 + - 4208.28 + - 282.8 + - 15-422-500 -> -9861.55 | U39: =-423-319-320-500-1178-1238-1000-1767-1212-180-12 -> -8149 | V39: =-424-320-1212-1767-1212-1767-15-1767-45-1452-552-169 -> -10702 | W39: =-425-320-1767-419-30-3735-419-88 -> -7203 | X39: =-426-321-322-281-1767-345-210 -> -3672 | Y39: =-282-409-500-642-409-295-1767 -> -4304 | Z39: =-427-323-283-365-500-417-5288-15-642-295 -> -8555 | AA39: =-409-348 -> -757 | AB39: -2829 | AC39: -500 | AD39: =- 1330.41 + - 367.48 + - 500 + - 408.89 -> -2606.78
B40: ='PLAN Zahlen'!B42 -> 2.5. | C40: Kraftstoff | E40: 0 | F40: 0 | G40: 0 | H40: 0 | I40: 0 | J40: 0 | K40: 0 | L40: 0 | M40: 0 | N40: 0 | P40: -2322 | Q40: -4753 | R40: -8578 | S40: -6573 | T40: -9304 | U40: -8805 | V40: -4288 | Y40: =-1310-4518-20 -> -5848 | Z40: -1360 | AB40: -6537
B41: ='PLAN Zahlen'!B43 -> 2.6. | C41: ='PLAN Zahlen'!C43 -> Miete Geschäftsräume | E41: 0 | F41: 0 | G41: 0 | H41: 0 | I41: 0 | J41: 0 | K41: 0 | L41: 0 | M41: 0 | N41: 0 | W41: 392 | X41: -392 | Y41: -392 | Z41: -392 | AB41: -784
B42: ='PLAN Zahlen'!B44 -> 2.7. | C42: Rückzahlung Darlehen | E42: 0 | F42: 0 | G42: 0 | H42: 0 | I42: 0 | J42: 0 | K42: 0 | L42: 0 | N42: 0 | U42: -3000 | X42: -2100
B43: ='PLAN Zahlen'!B45 -> 2.8. | C43: ='PLAN Zahlen'!C45 -> Versicherungen | E43: 0 | F43: 0 | G43: 0 | H43: 0 | I43: 0 | J43: 0 | K43: 0 | L43: 0 | M43: - | P43: =- 35.7 + - 7.94 +- 2493.02 + - 74.97 -> -2611.63 | Q43: -41.65 | R43: -83.3 | S43: =- 83.3 + - 2510.9 -> -2594.2 | T43: =-2511-83-51 -> -2645 | U43: =- 124.95 + - 462.9 + - 462.9 -> -1050.75 | V43: =- 124.95 + - 54 + - 231.45 -> -410.4 | W43: =- 6130.06 + - 275.77 + - 124.95 + - 181.45 + - 536.98-6133 -> -13382.21 | X43: =-343-125-231-232-343-343-200 -> -1817 | Y43: -1669 | Z43: -343 | AA43: -1200 | AB43: =-4024-375 -> -4399 | AD43: -163.6
B44: ='PLAN Zahlen'!B46 -> 2.9. | C44: Reisekosten | E44: 0 | F44: 0 | G44: 0 | H44: 0 | I44: 0 | J44: 0 | K44: 0 | L44: 0 | M44: 0 | N44: 0 | P44: -1011
B45: ='PLAN Zahlen'!B47 -> 2.10. | C45: ='PLAN Zahlen'!C47 -> Beratungskosten | E45: 0 | F45: 0 | G45: 0 | H45: 0 | I45: 0 | J45: 0 | K45: 0 | L45: 0 | M45: -2380 | N45: 0 | S45: -1401 | V45: -1773 | X45: -1595 | Z45: -436
B46: ='PLAN Zahlen'!B48 -> 2.11. | C46: Reparaturen Kfz | E46: 0 | F46: 0 | G46: 0 | H46: 0 | I46: 0 | J46: 0 | K46: 0 | L46: 0 | M46: 0 | N46: 0 | V46: =-1452-552-169 -> -2173 | AB46: -750 | AC46: -932
B47: ='PLAN Zahlen'!B49 -> 2.12. | C47: ='PLAN Zahlen'!C49 -> Zinsen/Gebühren (z.B. InsoGeld) | E47: 0 | F47: 0 | G47: 0 | H47: 0 | I47: 0 | J47: 0 | K47: 0 | L47: 0 | M47: 0 | T47: -78 | U47: -256 | V47: =-76-88 -> -164 | Y47: -63 | Z47: -221 | AB47: -588
B48: ='PLAN Zahlen'!B50 -> 2.13. | C48: Privatentnahme | E48: 0 | N48: -1000 | O48: -1000 | P48: -2484 | R48: -4650 | S48: -3100 | T48: -7330 | U48: -10664 | V48: -26160 | W48: -6267 | X48: -6211 | Y48: -8520 | Z48: -10450 | AA48: -1000 | AB48: -542 | AC48: -1189
...

Sheet Vergleich
B2: PLAN / IST VERGLEICH
E3: INSOLVENZ-
E4: ANTRAG | F4: ='PLAN Zahlen'!F7 -> August | H4: ='PLAN Zahlen'!G7 -> September | J4: ='PLAN Zahlen'!H7 -> Oktober | L4: ='PLAN Zahlen'!I7 -> November | N4: ='PLAN Zahlen'!J7 -> Dezember | P4: ='PLAN Zahlen'!K7 -> Januar | R4: ='PLAN Zahlen'!L7 -> Februar | T4: ='PLAN Zahlen'!M7 -> März | V4: ='PLAN Zahlen'!N7 -> April | X4: ='PLAN Zahlen'!O7 -> Mai | Z4: ='PLAN Zahlen'!P7 -> Juni | AB4: ='PLAN Zahlen'!Q7 -> Juli | AD4: ='PLAN Zahlen'!R7 -> August | AF4: ='PLAN Zahlen'!S7 -> September
F5: PLAN | G5: IST | H5: PLAN | I5: IST | J5: PLAN | K5: IST | L5: PLAN | M5: IST | N5: PLAN | O5: IST | P5: PLAN | Q5: IST | R5: PLAN | S5: IST | T5: PLAN | U5: IST | V5: PLAN | W5: IST | X5: PLAN | Y5: IST
C6: Anfangsbestand | E6: ='PLAN Zahlen'!E9 -> 0 | F6: ='PLAN Zahlen'!F9 -> 0 | G6: ='IST Zahlen'!F7 -> 0 | H6: ='PLAN Zahlen'!G9 -> 1334.92 | I6: ='IST Zahlen'!G7 -> 0 | J6: ='PLAN Zahlen'!H9 -> 3941.92 | K6: ='IST Zahlen'!H7 -> 0 | L6: ='PLAN Zahlen'!I9 -> 6282.92 | M6: ='IST Zahlen'!I7 -> 0 | N6: ='PLAN Zahlen'!J9 -> 8623.92 | O6: ='IST Zahlen'!J7 -> 0 | P6: ='PLAN Zahlen'!K9 -> 10964.92 | Q6: ='IST Zahlen'!K7 -> 0 | R6: ='PLAN Zahlen'!L9 -> 11855.92 | S6: ='IST Zahlen'!L7 -> 0 | T6: ='PLAN Zahlen'!M9 -> 12746.92 | U6: ='IST Zahlen'!M7 -> 0 | V6: ='PLAN Zahlen'!N9 -> 13637.92 | W6: ='IST Zahlen'!N7 -> 44 | X6: ='PLAN Zahlen'!O9 -> 14528.92 | Y6: ='IST Zahlen'!O7 -> 16713.39 | Z6: ='PLAN Zahlen'!P9 -> 15419.92 | AA6: ='IST Zahlen'!P7 -> 5076.52 | AB6: ='PLAN Zahlen'!Q9 -> 16310.92 | AC6: ='IST Zahlen'!Q7 -> 299.72 | AD6: ='PLAN Zahlen'!R9 -> 17201.92 | AE6: ='IST Zahlen'!R7 -> 9554.42 | AF6: ='PLAN Zahlen'!S9 -> 18092.92 | AG6: ='IST Zahlen'!S7 -> 13990.66
B8: 1. | C8: Zahlungseingänge | F8: ='PLAN Zahlen'!F11 -> 0 | G8: ='IST Zahlen'!F9 -> 0 | H8: ='PLAN Zahlen'!G11 -> 0 | I8: ='IST Zahlen'!G9 -> 0 | J8: ='PLAN Zahlen'!H11 -> 0 | K8: ='IST Zahlen'!H9 -> 0 | L8: ='PLAN Zahlen'!I11 -> 0 | M8: ='IST Zahlen'!I9 -> 0 | N8: ='PLAN Zahlen'!J11 -> 0 | O8: ='IST Zahlen'!J9 -> 0 | P8: ='PLAN Zahlen'!K11 -> 0 | Q8: ='IST Zahlen'!K9 -> 0 | R8: ='PLAN Zahlen'!L11 -> 0 | S8: ='IST Zahlen'!L9 -> 0 | T8: ='PLAN Zahlen'!M11 -> 0 | U8: ='IST Zahlen'!M9 -> 0 | V8: ='PLAN Zahlen'!N11 -> 0 | W8: ='IST Zahlen'!N9 -> 0 | X8: ='PLAN Zahlen'!O11 -> 0 | Y8: ='IST Zahlen'!O9 -> 0 | Z8: ='PLAN Zahlen'!P11 -> 0 | AA8: ='IST Zahlen'!P9 -> 0 | AB8: ='PLAN Zahlen'!Q11 -> 0 | AC8: ='IST Zahlen'!Q9 -> 0 | AD8: ='PLAN Zahlen'!R11 -> 0 | AE8: ='IST Zahlen'!R9 -> 0 | AF8: ='PLAN Zahlen'!S11 -> 0 | AG8: ='IST Zahlen'!S9 -> 0
F9: ='PLAN Zahlen'!F12 -> 0 | G9: ='IST Zahlen'!F10 -> 0 | H9: ='PLAN Zahlen'!G12 -> 0 | I9: ='IST Zahlen'!G10 -> 0 | J9: ='PLAN Zahlen'!H12 -> 0 | K9: ='IST Zahlen'!H10 -> 0 | L9: ='PLAN Zahlen'!I12 -> 0 | M9: ='IST Zahlen'!I10 -> 0 | N9: ='PLAN Zahlen'!J12 -> 0 | O9: ='IST Zahlen'!J10 -> 0 | P9: ='PLAN Zahlen'!K12 -> 0 | Q9: ='IST Zahlen'!K10 -> 0 | R9: ='PLAN Zahlen'!L12 -> 0 | S9: ='IST Zahlen'!L10 -> 0 | T9: ='PLAN Zahlen'!M12 -> 0 | U9: ='IST Zahlen'!M10 -> 0 | V9: ='PLAN Zahlen'!N12 -> 0 | W9: ='IST Zahlen'!N10 -> 0 | X9: ='PLAN Zahlen'!O12 -> 0 | Y9: ='IST Zahlen'!O10 -> 0 | Z9: ='PLAN Zahlen'!P12 -> 0 | AA9: ='IST Zahlen'!P10 -> 0 | AB9: ='PLAN Zahlen'!Q12 -> 0 | AC9: ='IST Zahlen'!Q10 -> 0 | AD9: ='PLAN Zahlen'!R12 -> 0 | AE9: ='IST Zahlen'!R10 -> 0 | AF9: ='PLAN Zahlen'!S12 -> 0 | AG9: ='IST Zahlen'!S10 -> 0
B10: ='PLAN Zahlen'!B13 -> 1.1. | C10: ='PLAN Zahlen'!C13 -> Neukunden (Leistung ab Insolvenzantrag) | F10: ='PLAN Zahlen'!F13 -> 0 | G10: ='IST Zahlen'!F11 -> 0 | H10: ='PLAN Zahlen'!G13 -> 0 | I10: ='IST Zahlen'!G11 -> 0 | J10: ='PLAN Zahlen'!H13 -> 0 | K10: ='IST Zahlen'!H11 -> 0 | L10: ='PLAN Zahlen'!I13 -> 0 | M10: ='IST Zahlen'!I11 -> 0 | N10: ='PLAN Zahlen'!J13 -> 0 | O10: ='IST Zahlen'!J11 -> 0 | P10: ='PLAN Zahlen'!K13 -> 0 | Q10: ='IST Zahlen'!K11 -> 0 | R10: ='PLAN Zahlen'!L13 -> 0 | S10: ='IST Zahlen'!L11 -> 0 | T10: ='PLAN Zahlen'!M13 -> 0 | U10: ='IST Zahlen'!M11 -> 0 | V10: ='PLAN Zahlen'!N13 -> 0 | W10: ='IST Zahlen'!N11 -> 0 | X10: ='PLAN Zahlen'!O13 -> 0 | Y10: ='IST Zahlen'!O11 -> 0 | Z10: ='PLAN Zahlen'!P13 -> 0 | AA10: ='IST Zahlen'!P11 -> 447.44 | AB10: ='PLAN Zahlen'!Q13 -> 0 | AC10: ='IST Zahlen'!Q11 -> 0 | AD10: ='PLAN Zahlen'!R13 -> 0 | AE10: ='IST Zahlen'!R11 -> 0 | AF10: ='PLAN Zahlen'!S13 -> 0 | AG10: ='IST Zahlen'!S11 -> 0
B11: ='PLAN Zahlen'!B14 -> 0 | C11: ='PLAN Zahlen'!C14 -> Kundeneinzahlungen | E11: 0 | F11: ='PLAN Zahlen'!F14 -> 0 | G11: ='IST Zahlen'!F12 -> 0 | H11: ='PLAN Zahlen'!G14 -> 0 | I11: ='IST Zahlen'!G12 -> 0 | J11: ='PLAN Zahlen'!H14 -> 0 | K11: ='IST Zahlen'!H12 -> 0 | L11: ='PLAN Zahlen'!I14 -> 0 | M11: ='IST Zahlen'!I12 -> 0 | N11: ='PLAN Zahlen'!J14 -> 0 | O11: ='IST Zahlen'!J12 -> 0 | P11: ='PLAN Zahlen'!K14 -> 0 | Q11: ='IST Zahlen'!K12 -> 0 | R11: ='PLAN Zahlen'!L14 -> 0 | S11: ='IST Zahlen'!L12 -> 0 | T11: ='PLAN Zahlen'!M14 -> 0 | U11: ='IST Zahlen'!M12 -> 0 | V11: ='PLAN Zahlen'!N14 -> 0 | W11: ='IST Zahlen'!N12 -> 0 | X11: ='PLAN Zahlen'!O14 -> 0 | Y11: ='IST Zahlen'!O12 -> 0 | Z11: ='PLAN Zahlen'!P14 -> 0 | AA11: ='IST Zahlen'!P12 -> 0 | AB11: ='PLAN Zahlen'!Q14 -> 0 | AC11: ='IST Zahlen'!Q12 -> 0 | AD11: ='PLAN Zahlen'!R14 -> 0 | AE11: ='IST Zahlen'!R12 -> 0 | AF11: ='PLAN Zahlen'!S14 -> 0 | AG11: ='IST Zahlen'!S12 -> 0
B12: ='PLAN Zahlen'!B15 -> 0 | C12: ='PLAN Zahlen'!C15 -> Factoring | E12: 0 | F12: ='PLAN Zahlen'!F15 -> 0 | G12: ='IST Zahlen'!F13 -> 0 | H12: ='PLAN Zahlen'!G15 -> 0 | I12: ='IST Zahlen'!G13 -> 0 | J12: ='PLAN Zahlen'!H15 -> 0 | K12: ='IST Zahlen'!H13 -> 0 | L12: ='PLAN Zahlen'!I15 -> 0 | M12: ='IST Zahlen'!I13 -> 0 | N12: ='PLAN Zahlen'!J15 -> 0 | O12: ='IST Zahlen'!J13 -> 0 | P12: ='PLAN Zahlen'!K15 -> 0 | Q12: ='IST Zahlen'!K13 -> 0 | R12: ='PLAN Zahlen'!L15 -> 0 | S12: ='IST Zahlen'!L13 -> 0 | T12: ='PLAN Zahlen'!M15 -> 0 | U12: ='IST Zahlen'!M13 -> 0 | V12: ='PLAN Zahlen'!N15 -> 0 | W12: ='IST Zahlen'!N13 -> 0 | X12: ='PLAN Zahlen'!O15 -> 0 | Y12: ='IST Zahlen'!O13 -> 0 | Z12: ='PLAN Zahlen'!P15 -> 0 | AA12: ='IST Zahlen'!P13 -> 0 | AB12: ='PLAN Zahlen'!Q15 -> 0 | AC12: ='IST Zahlen'!Q13 -> 0 | AD12: ='PLAN Zahlen'!R15 -> 0 | AE12: ='IST Zahlen'!R13 -> 0 | AF12: ='PLAN Zahlen'!S15 -> 0 | AG12: ='IST Zahlen'!S13 -> 0
B13: ='PLAN Zahlen'!B16 -> 0 | C13: ='PLAN Zahlen'!C16 -> Factoring (Sicherungseinbehalt) | E13: 0 | F13: ='PLAN Zahlen'!F16 -> 0 | G13: ='IST Zahlen'!F14 -> 0 | H13: ='PLAN Zahlen'!G16 -> 0 | I13: ='IST Zahlen'!G14 -> 0 | J13: ='PLAN Zahlen'!H16 -> 0 | K13: ='IST Zahlen'!H14 -> 0 | L13: ='PLAN Zahlen'!I16 -> 0 | M13: ='IST Zahlen'!I14 -> 0 | N13: ='PLAN Zahlen'!J16 -> 0 | O13: ='IST Zahlen'!J14 -> 0 | P13: ='PLAN Zahlen'!K16 -> 0 | Q13: ='IST Zahlen'!K14 -> 0 | R13: ='PLAN Zahlen'!L16 -> 0 | S13: ='IST Zahlen'!L14 -> 0 | T13: ='PLAN Zahlen'!M16 -> 0 | U13: ='IST Zahlen'!M14 -> 0 | V13: ='PLAN Zahlen'!N16 -> 0 | W13: ='IST Zahlen'!N14 -> 0 | X13: ='PLAN Zahlen'!O16 -> 0 | Y13: ='IST Zahlen'!O14 -> 0 | Z13: ='PLAN Zahlen'!P16 -> 0 | AA13: ='IST Zahlen'!P14 -> 0 | AB13: ='PLAN Zahlen'!Q16 -> 0 | AC13: ='IST Zahlen'!Q14 -> 0 | AD13: ='PLAN Zahlen'!R16 -> 0 | AE13: ='IST Zahlen'!R14 -> 0 | AF13: ='PLAN Zahlen'!S16 -> 0 | AG13: ='IST Zahlen'!S14 -> 0
B14: ='PLAN Zahlen'!B17 -> 1.2. | C14: ='PLAN Zahlen'!C17 -> Altkunden (Leistung vor Insolvenzantrag) | E14: 0 | F14: ='PLAN Zahlen'!F17 -> 24130.84 | G14: ='IST Zahlen'!F15 -> 0 | H14: ='PLAN Zahlen'!G17 -> 26000 | I14: ='IST Zahlen'!G15 -> 0 | J14: ='PLAN Zahlen'!H17 -> 32000 | K14: ='IST Zahlen'!H15 -> 0 | L14: ='PLAN Zahlen'!I17 -> 32000 | M14: ='IST Zahlen'!I15 -> 0 | N14: ='PLAN Zahlen'!J17 -> 32000 | O14: ='IST Zahlen'!J15 -> 0 | P14: ='PLAN Zahlen'!K17 -> 32000 | Q14: ='IST Zahlen'!K15 -> 0 | R14: ='PLAN Zahlen'!L17 -> 32000 | S14: ='IST Zahlen'!L15 -> 0 | T14: ='PLAN Zahlen'!M17 -> 32000 | U14: ='IST Zahlen'!M15 -> - | V14: ='PLAN Zahlen'!N17 -> 32000 | W14: ='IST Zahlen'!N15 -> 0 | X14: ='PLAN Zahlen'!O17 -> 32000 | Y14: ='IST Zahlen'!O15 -> 0 | Z14: ='PLAN Zahlen'!P17 -> 32000 | AA14: ='IST Zahlen'!P15 -> - | AB14: ='PLAN Zahlen'!Q17 -> 32000 | AC14: ='IST Zahlen'!Q15 -> 11667.96 | AD14: ='PLAN Zahlen'!R17 -> 32000 | AE14: ='IST Zahlen'!R15 -> 15167.2 | AF14: ='PLAN Zahlen'!S17 -> 32000 | AG14: ='IST Zahlen'!S15 -> 17761
B15: ='PLAN Zahlen'!B18 -> 1.3. | C15: ='PLAN Zahlen'!C18 -> Sonstige Eingänge | E15: 0 | F15: ='PLAN Zahlen'!F18 -> 0 | G15: ='IST Zahlen'!#REF! -> #REF! | H15: ='PLAN Zahlen'!G18 -> 0 | I15: ='IST Zahlen'!G16 -> 0 | J15: ='PLAN Zahlen'!H18 -> 0 | K15: ='IST Zahlen'!H16 -> 0 | L15: ='PLAN Zahlen'!I18 -> 0 | M15: ='IST Zahlen'!I16 -> 0 | N15: ='PLAN Zahlen'!J18 -> 0 | O15: ='IST Zahlen'!J16 -> 0 | P15: ='PLAN Zahlen'!K18 -> 0 | Q15: ='IST Zahlen'!K16 -> 0 | R15: ='PLAN Zahlen'!L18 -> 0 | S15: ='IST Zahlen'!L16 -> 0 | T15: ='PLAN Zahlen'!M18 -> 0 | U15: ='IST Zahlen'!M16 -> 0 | V15: ='PLAN Zahlen'!N18 -> 0 | W15: ='IST Zahlen'!N16 -> 0 | X15: ='PLAN Zahlen'!O18 -> 0 | Y15: ='IST Zahlen'!O16 -> 412.2 | Z15: ='PLAN Zahlen'!P18 -> 0 | AA15: ='IST Zahlen'!P16 -> 0 | AB15: ='PLAN Zahlen'!Q18 -> 0 | AC15: ='IST Zahlen'!Q16 -> 0 | AD15: ='PLAN Zahlen'!R18 -> 0 | AE15: ='IST Zahlen'!R16 -> 0 | AF15: ='PLAN Zahlen'!S18 -> 0 | AG15: ='IST Zahlen'!S16 -> 0
B16: ='PLAN Zahlen'!B19 -> 1.4. | C16: ='PLAN Zahlen'!C19 -> 0 | E16: 0 | F16: ='PLAN Zahlen'!F19 -> 0 | G16: ='IST Zahlen'!F16 -> 0 | H16: ='PLAN Zahlen'!G19 -> 0 | I16: ='IST Zahlen'!G17 -> 0 | J16: ='PLAN Zahlen'!H19 -> 0 | K16: ='IST Zahlen'!H17 -> 0 | L16: ='PLAN Zahlen'!I19 -> 0 | M16: ='IST Zahlen'!I17 -> 0 | N16: ='PLAN Zahlen'!J19 -> 0 | O16: ='IST Zahlen'!J17 -> 0 | P16: ='PLAN Zahlen'!K19 -> 0 | Q16: ='IST Zahlen'!K17 -> 0 | R16: ='PLAN Zahlen'!L19 -> 0 | S16: ='IST Zahlen'!L17 -> 0 | T16: ='PLAN Zahlen'!M19 -> 0 | U16: ='IST Zahlen'!M17 -> 2400 | V16: ='PLAN Zahlen'!N19 -> 0 | W16: ='IST Zahlen'!N17 -> 21000 | X16: ='PLAN Zahlen'!O19 -> 0 | Y16: ='IST Zahlen'!O17 -> 0 | Z16: ='PLAN Zahlen'!P19 -> 0 | AA16: ='IST Zahlen'!P17 -> 7000 | AB16: ='PLAN Zahlen'!Q19 -> 0 | AC16: ='IST Zahlen'!Q17 -> 7000 | AD16: ='PLAN Zahlen'!R19 -> 0 | AE16: ='IST Zahlen'!R17 -> 790 | AF16: ='PLAN Zahlen'!S19 -> 0 | AG16: ='IST Zahlen'!S17 -> 3850
B17: ='PLAN Zahlen'!B20 -> 0 | C17: ='PLAN Zahlen'!C20 -> 0 | E17: 0 | F17: ='PLAN Zahlen'!F20 -> 0 | G17: ='IST Zahlen'!F18 -> 0 | H17: ='PLAN Zahlen'!G20 -> 0 | I17: ='IST Zahlen'!G18 -> 0 | J17: ='PLAN Zahlen'!H20 -> 0 | K17: ='IST Zahlen'!H18 -> 0 | L17: ='PLAN Zahlen'!I20 -> 0 | M17: ='IST Zahlen'!I18 -> 0 | N17: ='PLAN Zahlen'!J20 -> 0 | O17: ='IST Zahlen'!J18 -> 0 | P17: ='PLAN Zahlen'!K20 -> 0 | Q17: ='IST Zahlen'!K18 -> 0 | R17: ='PLAN Zahlen'!L20 -> 0 | S17: ='IST Zahlen'!L18 -> 0 | T17: ='PLAN Zahlen'!M20 -> 0 | U17: ='IST Zahlen'!M18 -> 0 | V17: ='PLAN Zahlen'!N20 -> 0 | W17: ='IST Zahlen'!N18 -> 0 | X17: ='PLAN Zahlen'!O20 -> 0 | Y17: ='IST Zahlen'!O18 -> 0 | Z17: ='PLAN Zahlen'!P20 -> 0 | AA17: ='IST Zahlen'!P18 -> 0 | AB17: ='PLAN Zahlen'!Q20 -> 0 | AC17: ='IST Zahlen'!Q18 -> 0 | AD17: ='PLAN Zahlen'!R20 -> 0 | AE17: ='IST Zahlen'!R18 -> 17000 | AF17: ='PLAN Zahlen'!S20 -> 0 | AG17: ='IST Zahlen'!S18 -> 3000
B18: ='PLAN Zahlen'!B21 -> 0 | C18: ='PLAN Zahlen'!C21 -> 0 | E18: 0 | F18: ='PLAN Zahlen'!F21 -> 0 | G18: ='IST Zahlen'!F19 -> 0 | H18: ='PLAN Zahlen'!G21 -> 0 | I18: ='IST Zahlen'!G19 -> 0 | J18: ='PLAN Zahlen'!H21 -> 0 | K18: ='IST Zahlen'!H19 -> 0 | L18: ='PLAN Zahlen'!I21 -> 0 | M18: ='IST Zahlen'!I19 -> 0 | N18: ='PLAN Zahlen'!J21 -> 0 | O18: ='IST Zahlen'!J19 -> 0 | P18: ='PLAN Zahlen'!K21 -> 0 | Q18: ='IST Zahlen'!K19 -> 0 | R18: ='PLAN Zahlen'!L21 -> 0 | S18: ='IST Zahlen'!L19 -> 0 | T18: ='PLAN Zahlen'!M21 -> 0 | U18: ='IST Zahlen'!M19 -> 24 | V18: ='PLAN Zahlen'!N21 -> 0 | W18: ='IST Zahlen'!N19 -> 0 | X18: ='PLAN Zahlen'!O21 -> 0 | Y18: ='IST Zahlen'!O19 -> 0 | Z18: ='PLAN Zahlen'!P21 -> 0 | AA18: ='IST Zahlen'!P19 -> 822 | AB18: ='PLAN Zahlen'!Q21 -> 0 | AC18: ='IST Zahlen'!Q19 -> 0 | AD18: ='PLAN Zahlen'!R21 -> 0 | AE18: ='IST Zahlen'!R19 -> 7552 | AF18: ='PLAN Zahlen'!S21 -> 0 | AG18: ='IST Zahlen'!S19 -> 0
B19: ='PLAN Zahlen'!B22 -> 0 | C19: ='PLAN Zahlen'!C22 -> 0 | E19: 0 | F19: ='PLAN Zahlen'!F22 -> 0 | G19: ='IST Zahlen'!F20 -> 0 | H19: ='PLAN Zahlen'!G22 -> 0 | I19: ='IST Zahlen'!G20 -> 0 | J19: ='PLAN Zahlen'!H22 -> 0 | K19: ='IST Zahlen'!H20 -> 0 | L19: ='PLAN Zahlen'!I22 -> 0 | M19: ='IST Zahlen'!I20 -> 0 | N19: ='PLAN Zahlen'!J22 -> 0 | O19: ='IST Zahlen'!J20 -> 0 | P19: ='PLAN Zahlen'!K22 -> 0 | Q19: ='IST Zahlen'!K20 -> 0 | R19: ='PLAN Zahlen'!L22 -> 0 | S19: ='IST Zahlen'!L20 -> 0 | T19: ='PLAN Zahlen'!M22 -> 0 | U19: ='IST Zahlen'!M20 -> 0 | V19: ='PLAN Zahlen'!N22 -> 0 | W19: ='IST Zahlen'!N20 -> 0 | X19: ='PLAN Zahlen'!O22 -> 0 | Y19: ='IST Zahlen'!O20 -> 0 | Z19: ='PLAN Zahlen'!P22 -> 0 | AA19: ='IST Zahlen'!P20 -> 0 | AB19: ='PLAN Zahlen'!Q22 -> 0 | AC19: ='IST Zahlen'!Q20 -> 0 | AD19: ='PLAN Zahlen'!R22 -> 0 | AE19: ='IST Zahlen'!R20 -> 0 | AF19: ='PLAN Zahlen'!S22 -> 0 | AG19: ='IST Zahlen'!S20 -> 0
B20: ='PLAN Zahlen'!B23 -> 0 | C20: ='PLAN Zahlen'!C23 -> 0 | E20: 0 | F20: ='PLAN Zahlen'!F23 -> 0 | G20: ='IST Zahlen'!F21 -> 0 | H20: ='PLAN Zahlen'!G23 -> 0 | I20: ='IST Zahlen'!G21 -> 0 | J20: ='PLAN Zahlen'!H23 -> 0 | K20: ='IST Zahlen'!H21 -> 0 | L20: ='PLAN Zahlen'!I23 -> 0 | M20: ='IST Zahlen'!I21 -> 0 | N20: ='PLAN Zahlen'!J23 -> 0 | O20: ='IST Zahlen'!J21 -> 0 | P20: ='PLAN Zahlen'!K23 -> 0 | Q20: ='IST Zahlen'!K21 -> 0 | R20: ='PLAN Zahlen'!L23 -> 0 | S20: ='IST Zahlen'!L21 -> 0 | T20: ='PLAN Zahlen'!M23 -> 0 | U20: ='IST Zahlen'!M21 -> 0 | V20: ='PLAN Zahlen'!N23 -> 0 | W20: ='IST Zahlen'!N21 -> 0 | X20: ='PLAN Zahlen'!O23 -> 0 | Y20: ='IST Zahlen'!O21 -> 0 | Z20: ='PLAN Zahlen'!P23 -> 0 | AA20: ='IST Zahlen'!P21 -> 0 | AB20: ='PLAN Zahlen'!Q23 -> 0 | AC20: ='IST Zahlen'!Q21 -> 0 | AD20: ='PLAN Zahlen'!R23 -> 0 | AE20: ='IST Zahlen'!R21 -> 2782 | AF20: ='PLAN Zahlen'!S23 -> 0 | AG20: ='IST Zahlen'!S21 -> 4308
B21: ='PLAN Zahlen'!B24 -> 0 | C21: ='PLAN Zahlen'!C24 -> 0 | E21: 0 | F21: ='PLAN Zahlen'!F24 -> 0 | G21: ='IST Zahlen'!F22 -> 0 | H21: ='PLAN Zahlen'!G24 -> 0 | I21: ='IST Zahlen'!G22 -> 0 | J21: ='PLAN Zahlen'!H24 -> 0 | K21: ='IST Zahlen'!H22 -> 0 | L21: ='PLAN Zahlen'!I24 -> 0 | M21: ='IST Zahlen'!I22 -> 0 | N21: ='PLAN Zahlen'!J24 -> 0 | O21: ='IST Zahlen'!J22 -> 0 | P21: ='PLAN Zahlen'!K24 -> 0 | Q21: ='IST Zahlen'!K22 -> 0 | R21: ='PLAN Zahlen'!L24 -> 0 | S21: ='IST Zahlen'!L22 -> 0 | T21: ='PLAN Zahlen'!M24 -> 0 | U21: ='IST Zahlen'!M22 -> 0 | V21: ='PLAN Zahlen'!N24 -> 0 | W21: ='IST Zahlen'!N22 -> 0 | X21: ='PLAN Zahlen'!O24 -> 0 | Y21: ='IST Zahlen'!O22 -> 0 | Z21: ='PLAN Zahlen'!P24 -> 0 | AA21: ='IST Zahlen'!P22 -> 0 | AB21: ='PLAN Zahlen'!Q24 -> 0 | AC21: ='IST Zahlen'!Q22 -> 0 | AD21: ='PLAN Zahlen'!R24 -> 0 | AE21: ='IST Zahlen'!R22 -> 0 | AF21: ='PLAN Zahlen'!S24 -> 0 | AG21: ='IST Zahlen'!S22 -> 0
B22: ='PLAN Zahlen'!B25 -> 0 | C22: ='PLAN Zahlen'!C25 -> 0 | E22: 0 | F22: ='PLAN Zahlen'!F25 -> 0 | G22: ='IST Zahlen'!F23 -> 0 | H22: ='PLAN Zahlen'!G25 -> 0 | I22: ='IST Zahlen'!G23 -> 0 | J22: ='PLAN Zahlen'!H25 -> 0 | K22: ='IST Zahlen'!H23 -> 0 | L22: ='PLAN Zahlen'!I25 -> 0 | M22: ='IST Zahlen'!I23 -> 0 | N22: ='PLAN Zahlen'!J25 -> 0 | O22: ='IST Zahlen'!J23 -> 0 | P22: ='PLAN Zahlen'!K25 -> 0 | Q22: ='IST Zahlen'!K23 -> 0 | R22: ='PLAN Zahlen'!L25 -> 0 | S22: ='IST Zahlen'!L23 -> 0 | T22: ='PLAN Zahlen'!M25 -> 0 | U22: ='IST Zahlen'!M23 -> 0 | V22: ='PLAN Zahlen'!N25 -> 0 | W22: ='IST Zahlen'!N23 -> 0 | X22: ='PLAN Zahlen'!O25 -> 0 | Y22: ='IST Zahlen'!O23 -> 0 | Z22: ='PLAN Zahlen'!P25 -> 0 | AA22: ='IST Zahlen'!P23 -> 0 | AB22: ='PLAN Zahlen'!Q25 -> 0 | AC22: ='IST Zahlen'!Q23 -> 0 | AD22: ='PLAN Zahlen'!R25 -> 0 | AE22: ='IST Zahlen'!R23 -> 0 | AF22: ='PLAN Zahlen'!S25 -> 0 | AG22: ='IST Zahlen'!S23 -> 0
F23: ='PLAN Zahlen'!F26 -> 0 | G23: ='IST Zahlen'!F24 -> 0 | H23: ='PLAN Zahlen'!G26 -> 0 | I23: ='IST Zahlen'!G24 -> 0 | J23: ='PLAN Zahlen'!H26 -> 0 | K23: ='IST Zahlen'!H24 -> 0 | L23: ='PLAN Zahlen'!I26 -> 0 | M23: ='IST Zahlen'!I24 -> 0 | N23: ='PLAN Zahlen'!J26 -> 0 | O23: ='IST Zahlen'!J24 -> 0 | P23: ='PLAN Zahlen'!K26 -> 0 | Q23: ='IST Zahlen'!K24 -> 0 | R23: ='PLAN Zahlen'!L26 -> 0 | S23: ='IST Zahlen'!L24 -> 0 | T23: ='PLAN Zahlen'!M26 -> 0 | U23: ='IST Zahlen'!M24 -> 0 | V23: ='PLAN Zahlen'!N26 -> 0 | W23: ='IST Zahlen'!N24 -> 0 | X23: ='PLAN Zahlen'!O26 -> 0 | Y23: ='IST Zahlen'!O24 -> 0 | Z23: ='PLAN Zahlen'!P26 -> 0 | AA23: ='IST Zahlen'!P24 -> 0 | AB23: ='PLAN Zahlen'!Q26 -> 0 | AC23: ='IST Zahlen'!Q24 -> 0 | AD23: ='PLAN Zahlen'!R26 -> 0 | AE23: ='IST Zahlen'!R24 -> 0 | AF23: ='PLAN Zahlen'!S26 -> 0 | AG23: ='IST Zahlen'!S24 -> 0
C24: Summe Zahlungseingänge | F24: ='PLAN Zahlen'!F27 -> 24130.84 | G24: ='IST Zahlen'!F25 -> 0 | H24: ='PLAN Zahlen'!G27 -> 26000 | I24: ='IST Zahlen'!G25 -> 0 | J24: ='PLAN Zahlen'!H27 -> 32000 | K24: ='IST Zahlen'!H25 -> 0 | L24: ='PLAN Zahlen'!I27 -> 32000 | M24: ='IST Zahlen'!I25 -> 0 | N24: ='PLAN Zahlen'!J27 -> 32000 | O24: ='IST Zahlen'!J25 -> 0 | P24: ='PLAN Zahlen'!K27 -> 32000 | Q24: ='IST Zahlen'!K25 -> 0 | R24: ='PLAN Zahlen'!L27 -> 32000 | S24: ='IST Zahlen'!L25 -> 0 | T24: ='PLAN Zahlen'!M27 -> 32000 | U24: ='IST Zahlen'!M25 -> 2424 | V24: ='PLAN Zahlen'!N27 -> 32000 | W24: ='IST Zahlen'!N25 -> 21000 | X24: ='PLAN Zahlen'!O27 -> 32000 | Y24: ='IST Zahlen'!O25 -> 412.2 | Z24: ='PLAN Zahlen'!P27 -> 32000 | AA24: ='IST Zahlen'!P25 -> 8269.44 | AB24: ='PLAN Zahlen'!Q27 -> 32000 | AC24: ='IST Zahlen'!Q25 -> 18667.96 | AD24: ='PLAN Zahlen'!R27 -> 32000 | AE24: ='IST Zahlen'!R25 -> 43291.2 | AF24: ='PLAN Zahlen'!S27 -> 32000 | AG24: ='IST Zahlen'!S25 -> 28919
I25: ='IST Zahlen'!G26 -> 0 | J25: ='PLAN Zahlen'!H28 -> 0 | K25: ='IST Zahlen'!H26 -> 0 | L25: ='PLAN Zahlen'!I28 -> 0 | M25: ='IST Zahlen'!I26 -> 0 | N25: ='PLAN Zahlen'!J28 -> 0 | O25: ='IST Zahlen'!J26 -> 0 | P25: ='PLAN Zahlen'!K28 -> 0 | Q25: ='IST Zahlen'!K26 -> 0 | R25: ='PLAN Zahlen'!L28 -> 0 | S25: ='IST Zahlen'!L26 -> 0 | T25: ='PLAN Zahlen'!M28 -> 0 | U25: ='IST Zahlen'!M26 -> 0 | V25: ='PLAN Zahlen'!N28 -> 0 | W25: ='IST Zahlen'!N26 -> 0 | X25: ='PLAN Zahlen'!O28 -> 0 | Y25: ='IST Zahlen'!O26 -> 0 | Z25: ='PLAN Zahlen'!P28 -> 0 | AA25: ='IST Zahlen'!P26 -> 0 | AB25: ='PLAN Zahlen'!Q28 -> 0 | AC25: ='IST Zahlen'!Q26 -> 0 | AD25: ='PLAN Zahlen'!R28 -> 0 | AE25: ='IST Zahlen'!R26 -> 0 | AF25: ='PLAN Zahlen'!S28 -> 0 | AG25: ='IST Zahlen'!S26 -> 0
B26: ='PLAN Zahlen'!B29 -> 2. | C26: Zahlungsausgänge | F26: ='PLAN Zahlen'!F29 -> 0 | G26: ='IST Zahlen'!F27 -> 0 | H26: ='PLAN Zahlen'!G29 -> 0 | I26: ='IST Zahlen'!G27 -> 0 | J26: ='PLAN Zahlen'!H29 -> 0 | K26: ='IST Zahlen'!H27 -> 0 | L26: ='PLAN Zahlen'!I29 -> 0 | M26: ='IST Zahlen'!I27 -> 0 | N26: ='PLAN Zahlen'!J29 -> 0 | O26: ='IST Zahlen'!J27 -> 0 | P26: ='PLAN Zahlen'!K29 -> 0 | Q26: ='IST Zahlen'!K27 -> 0 | R26: ='PLAN Zahlen'!L29 -> 0 | S26: ='IST Zahlen'!L27 -> 0 | T26: ='PLAN Zahlen'!M29 -> 0 | U26: ='IST Zahlen'!M27 -> 0 | V26: ='PLAN Zahlen'!N29 -> 0 | W26: ='IST Zahlen'!N27 -> 0 | X26: ='PLAN Zahlen'!O29 -> 0 | Y26: ='IST Zahlen'!O27 -> 0 | Z26: ='PLAN Zahlen'!P29 -> 0 | AA26: ='IST Zahlen'!P27 -> 0 | AB26: ='PLAN Zahlen'!Q29 -> 0 | AC26: ='IST Zahlen'!Q27 -> 0 | AD26: ='PLAN Zahlen'!R29 -> 0 | AE26: ='IST Zahlen'!R27 -> 0 | AF26: ='PLAN Zahlen'!S29 -> 0 | AG26: ='IST Zahlen'!S27 -> 0
F27: ='PLAN Zahlen'!F30 -> 0 | G27: ='IST Zahlen'!F28 -> 0 | H27: ='PLAN Zahlen'!G30 -> 0 | I27: ='IST Zahlen'!G28 -> 0 | J27: ='PLAN Zahlen'!H30 -> 0 | K27: ='IST Zahlen'!H28 -> 0 | L27: ='PLAN Zahlen'!I30 -> 0 | M27: ='IST Zahlen'!I28 -> 0 | N27: ='PLAN Zahlen'!J30 -> 0 | O27: ='IST Zahlen'!J28 -> 0 | P27: ='PLAN Zahlen'!K30 -> 0 | Q27: ='IST Zahlen'!K28 -> 0 | R27: ='PLAN Zahlen'!L30 -> 0 | S27: ='IST Zahlen'!L28 -> 0 | T27: ='PLAN Zahlen'!M30 -> 0 | U27: ='IST Zahlen'!M28 -> 0 | V27: ='PLAN Zahlen'!N30 -> 0 | W27: ='IST Zahlen'!N28 -> 0 | X27: ='PLAN Zahlen'!O30 -> 0 | Y27: ='IST Zahlen'!O28 -> 0 | Z27: ='PLAN Zahlen'!P30 -> 0 | AA27: ='IST Zahlen'!P28 -> 0 | AB27: ='PLAN Zahlen'!Q30 -> 0 | AC27: ='IST Zahlen'!Q28 -> 0 | AD27: ='PLAN Zahlen'!R30 -> 0 | AE27: ='IST Zahlen'!R28 -> 0 | AF27: ='PLAN Zahlen'!S30 -> 0 | AG27: ='IST Zahlen'!S28 -> 0
B28: ='PLAN Zahlen'!B31 -> 2.1. | C28: ='PLAN Zahlen'!C31 -> Materialkosten | E28: 0 | F28: ='PLAN Zahlen'!F31 -> 0 | G28: ='IST Zahlen'!F29 -> 0 | H28: ='PLAN Zahlen'!G31 -> 0 | I28: ='IST Zahlen'!G29 -> 0 | J28: ='PLAN Zahlen'!H31 -> 0 | K28: ='IST Zahlen'!H29 -> 0 | L28: ='PLAN Zahlen'!I31 -> 0 | M28: ='IST Zahlen'!I29 -> 0 | N28: ='PLAN Zahlen'!J31 -> 0 | O28: ='IST Zahlen'!J29 -> 0 | P28: ='PLAN Zahlen'!K31 -> 0 | Q28: ='IST Zahlen'!K29 -> 0 | R28: ='PLAN Zahlen'!L31 -> 0 | S28: ='IST Zahlen'!L29 -> 0 | T28: ='PLAN Zahlen'!M31 -> 0 | U28: ='IST Zahlen'!M29 -> 0 | V28: ='PLAN Zahlen'!N31 -> 0 | W28: ='IST Zahlen'!N29 -> 0 | X28: ='PLAN Zahlen'!O31 -> 0 | Y28: ='IST Zahlen'!O29 -> 0 | Z28: ='PLAN Zahlen'!P31 -> 0 | AA28: ='IST Zahlen'!P29 -> 0 | AB28: ='PLAN Zahlen'!Q31 -> 0 | AC28: ='IST Zahlen'!Q29 -> 0 | AD28: ='PLAN Zahlen'!R31 -> 0 | AE28: ='IST Zahlen'!R29 -> 0 | AF28: ='PLAN Zahlen'!S31 -> 0 | AG28: ='IST Zahlen'!S29 -> 0
B29: ='PLAN Zahlen'!B32 -> 2.2. | C29: ='PLAN Zahlen'!C32 -> Löhne und Gehälter | F29: ='PLAN Zahlen'!F32 -> 0 | G29: ='IST Zahlen'!F30 -> 0 | H29: ='PLAN Zahlen'!G32 -> 0 | I29: ='IST Zahlen'!G30 -> 0 | J29: ='PLAN Zahlen'!H32 -> 0 | K29: ='IST Zahlen'!H30 -> 0 | L29: ='PLAN Zahlen'!I32 -> 0 | M29: ='IST Zahlen'!I30 -> 0 | N29: ='PLAN Zahlen'!J32 -> 0 | O29: ='IST Zahlen'!J30 -> 0 | P29: ='PLAN Zahlen'!K32 -> 0 | Q29: ='IST Zahlen'!K30 -> 0 | R29: ='PLAN Zahlen'!L32 -> 0 | S29: ='IST Zahlen'!L30 -> 0 | T29: ='PLAN Zahlen'!M32 -> 0 | U29: ='IST Zahlen'!M30 -> 0 | V29: ='PLAN Zahlen'!N32 -> 0 | W29: ='IST Zahlen'!N30 -> 0 | X29: ='PLAN Zahlen'!O32 -> 0 | Y29: ='IST Zahlen'!O30 -> 0 | Z29: ='PLAN Zahlen'!P32 -> 0 | AA29: ='IST Zahlen'!P30 -> 0 | AB29: ='PLAN Zahlen'!Q32 -> 0 | AC29: ='IST Zahlen'!Q30 -> 0 | AD29: ='PLAN Zahlen'!R32 -> 0 | AE29: ='IST Zahlen'!R30 -> 0 | AF29: ='PLAN Zahlen'!S32 -> 0 | AG29: ='IST Zahlen'!S30 -> 0
B30: ='PLAN Zahlen'!B33 -> 0 | C30: ='PLAN Zahlen'!C33 -> Löhne | E30: 0 | F30: ='PLAN Zahlen'!F33 -> 0 | G30: ='IST Zahlen'!F31 -> 0 | H30: ='PLAN Zahlen'!G33 -> 0 | I30: ='IST Zahlen'!G31 -> 0 | J30: ='PLAN Zahlen'!H33 -> 0 | K30: ='IST Zahlen'!H31 -> 0 | L30: ='PLAN Zahlen'!I33 -> 0 | M30: ='IST Zahlen'!I31 -> 0 | N30: ='PLAN Zahlen'!J33 -> 0 | O30: ='IST Zahlen'!J31 -> 0 | P30: ='PLAN Zahlen'!K33 -> 0 | Q30: ='IST Zahlen'!K31 -> 0 | R30: ='PLAN Zahlen'!L33 -> 0 | S30: ='IST Zahlen'!L31 -> 0 | T30: ='PLAN Zahlen'!M33 -> 0 | U30: ='IST Zahlen'!M31 -> 0 | V30: ='PLAN Zahlen'!N33 -> 0 | W30: ='IST Zahlen'!N31 -> 0 | X30: ='PLAN Zahlen'!O33 -> 0 | Y30: ='IST Zahlen'!O31 -> 0 | Z30: ='PLAN Zahlen'!P33 -> 0 | AA30: ='IST Zahlen'!P31 -> 0 | AB30: ='PLAN Zahlen'!Q33 -> 0 | AC30: ='IST Zahlen'!Q31 -> 0 | AD30: ='PLAN Zahlen'!R33 -> 0 | AE30: ='IST Zahlen'!R31 -> 0 | AF30: ='PLAN Zahlen'!S33 -> 0 | AG30: ='IST Zahlen'!S31 -> 0
B31: ='PLAN Zahlen'!B34 -> 0 | C31: ='PLAN Zahlen'!C34 -> Gehälter | E31: 0 | F31: ='PLAN Zahlen'!F34 -> -3600 | G31: ='IST Zahlen'!F32 -> 0 | H31: ='PLAN Zahlen'!G34 -> -3600 | I31: ='IST Zahlen'!G32 -> 0 | J31: ='PLAN Zahlen'!H34 -> -5600 | K31: ='IST Zahlen'!H32 -> 0 | L31: ='PLAN Zahlen'!I34 -> -5600 | M31: ='IST Zahlen'!I32 -> 0 | N31: ='PLAN Zahlen'!J34 -> -5600 | O31: ='IST Zahlen'!J32 -> 0 | P31: ='PLAN Zahlen'!K34 -> -5600 | Q31: ='IST Zahlen'!K32 -> 0 | R31: ='PLAN Zahlen'!L34 -> -5600 | S31: ='IST Zahlen'!L32 -> 0 | T31: ='PLAN Zahlen'!M34 -> -5600 | U31: ='IST Zahlen'!M32 -> 0 | V31: ='PLAN Zahlen'!N34 -> -5600 | W31: ='IST Zahlen'!N32 -> -1376.89 | X31: ='PLAN Zahlen'!O34 -> -5600 | Y31: ='IST Zahlen'!O32 -> -1376.89 | Z31: ='PLAN Zahlen'!P34 -> -5600 | AA31: ='IST Zahlen'!P32 -> -1376.89 | AB31: ='PLAN Zahlen'!Q34 -> -5600 | AC31: ='IST Zahlen'!Q32 -> -1376.89 | AD31: ='PLAN Zahlen'!R34 -> -5600 | AE31: ='IST Zahlen'!R32 -> -5853.92 | AF31: ='PLAN Zahlen'!S34 -> -5600 | AG31: ='IST Zahlen'!S32 -> -5098.24
B32: ='PLAN Zahlen'!B35 -> 0 | C32: ='PLAN Zahlen'!C35 -> Sozialversicherung | E32: 0 | F32: ='PLAN Zahlen'!F35 -> -3180.54 | G32: ='IST Zahlen'!F33 -> 0 | H32: ='PLAN Zahlen'!G35 -> -2142 | I32: ='IST Zahlen'!G33 -> 0 | J32: ='PLAN Zahlen'!J35 -> -2400 | K32: ='IST Zahlen'!H33 -> 0 | L32: ='PLAN Zahlen'!K35 -> -2400 | M32: ='IST Zahlen'!I33 -> 0 | N32: ='PLAN Zahlen'!L35 -> -2400 | O32: ='IST Zahlen'!J33 -> 0 | P32: ='PLAN Zahlen'!M35 -> -2400 | Q32: ='IST Zahlen'!K33 -> 0 | R32: ='PLAN Zahlen'!N35 -> -2400 | S32: ='IST Zahlen'!L33 -> 0 | T32: ='PLAN Zahlen'!O35 -> -2400 | U32: ='IST Zahlen'!M33 -> 0 | V32: ='PLAN Zahlen'!P35 -> -2400 | W32: ='IST Zahlen'!N33 -> -822.14 | X32: ='PLAN Zahlen'!Q35 -> -2400 | Y32: ='IST Zahlen'!O33 -> -1644 | Z32: ='PLAN Zahlen'!R35 -> -2400 | AA32: ='IST Zahlen'!P33 -> -822.14 | AB32: ='PLAN Zahlen'!S35 -> -2400 | AC32: ='IST Zahlen'!Q33 -> -822.14 | AD32: ='PLAN Zahlen'!T35 -> -2400 | AE32: ='IST Zahlen'!R33 -> 0 | AF32: ='PLAN Zahlen'!U35 -> -2400 | AG32: ='IST Zahlen'!S33 -> -3095.4
B33: ='PLAN Zahlen'!B36 -> 0 | C33: ='PLAN Zahlen'!C36 -> Lohnsteuer | E33: 0 | F33: ='PLAN Zahlen'!F36 -> -250 | G33: ='IST Zahlen'!F34 -> 0 | H33: ='PLAN Zahlen'!G36 -> -250 | I33: ='IST Zahlen'!G34 -> 0 | J33: ='PLAN Zahlen'!H36 -> -300 | K33: ='IST Zahlen'!H34 -> 0 | L33: ='PLAN Zahlen'!I36 -> -300 | M33: ='IST Zahlen'!I34 -> 0 | N33: ='PLAN Zahlen'!J36 -> -300 | O33: ='IST Zahlen'!J34 -> 0 | P33: ='PLAN Zahlen'!K36 -> -300 | Q33: ='IST Zahlen'!K34 -> 0 | R33: ='PLAN Zahlen'!L36 -> -300 | S33: ='IST Zahlen'!L34 -> 0 | T33: ='PLAN Zahlen'!M36 -> -300 | U33: ='IST Zahlen'!M34 -> 0 | V33: ='PLAN Zahlen'!N36 -> -300 | W33: ='IST Zahlen'!N34 -> -143.58 | X33: ='PLAN Zahlen'!O36 -> -300 | Y33: ='IST Zahlen'!O34 -> -143.58 | Z33: ='PLAN Zahlen'!P36 -> -300 | AA33: ='IST Zahlen'!P34 -> -143.58 | AB33: ='PLAN Zahlen'!Q36 -> -300 | AC33: ='IST Zahlen'!Q34 -> -143.58 | AD33: ='PLAN Zahlen'!R36 -> -300 | AE33: ='IST Zahlen'!R34 -> -430.74 | AF33: ='PLAN Zahlen'!S36 -> -300 | AG33: ='IST Zahlen'!S34 -> -144.58
B34: ='PLAN Zahlen'!B37 -> 0 | C34: ='PLAN Zahlen'!C37 -> Sonstiges | E34: 0 | F34: ='PLAN Zahlen'!F37 -> 0 | G34: ='IST Zahlen'!F35 -> 0 | H34: ='PLAN Zahlen'!G37 -> 0 | I34: ='IST Zahlen'!G35 -> 0 | J34: ='PLAN Zahlen'!H37 -> 0 | K34: ='IST Zahlen'!H35 -> 0 | L34: ='PLAN Zahlen'!I37 -> 0 | M34: ='IST Zahlen'!I35 -> 0 | N34: ='PLAN Zahlen'!J37 -> 0 | O34: ='IST Zahlen'!J35 -> 0 | P34: ='PLAN Zahlen'!K37 -> 0 | Q34: ='IST Zahlen'!K35 -> 0 | R34: ='PLAN Zahlen'!L37 -> 0 | S34: ='IST Zahlen'!L35 -> 0 | T34: ='PLAN Zahlen'!M37 -> 0 | U34: ='IST Zahlen'!M35 -> 0 | V34: ='PLAN Zahlen'!N37 -> 0 | W34: ='IST Zahlen'!N35 -> 0 | X34: ='PLAN Zahlen'!O37 -> 0 | Y34: ='IST Zahlen'!O35 -> 0 | Z34: ='PLAN Zahlen'!P37 -> 0 | AA34: ='IST Zahlen'!P35 -> 0 | AB34: ='PLAN Zahlen'!Q37 -> 0 | AC34: ='IST Zahlen'!Q35 -> 0 | AD34: ='PLAN Zahlen'!R37 -> 0 | AE34: ='IST Zahlen'!R35 -> 0 | AF34: ='PLAN Zahlen'!S37 -> 0 | AG34: ='IST Zahlen'!S35 -> 0
B35: ='PLAN Zahlen'!B38 -> 0 | C35: ='PLAN Zahlen'!C38 -> Gesamtsumme | E35: 0 | F35: ='PLAN Zahlen'!F38 -> -7030.54 | G35: ='IST Zahlen'!F36 -> 0 | H35: ='PLAN Zahlen'!G38 -> -5992 | I35: ='IST Zahlen'!G36 -> 0 | J35: ='PLAN Zahlen'!H38 -> 0 | K35: ='IST Zahlen'!H36 -> 0 | L35: ='PLAN Zahlen'!I38 -> 0 | M35: ='IST Zahlen'!I36 -> 0 | N35: ='PLAN Zahlen'!J38 -> 0 | O35: ='IST Zahlen'!J36 -> 0 | P35: ='PLAN Zahlen'!K38 -> 0 | Q35: ='IST Zahlen'!K36 -> 0 | R35: ='PLAN Zahlen'!L38 -> 0 | S35: ='IST Zahlen'!L36 -> 0 | T35: ='PLAN Zahlen'!M38 -> 0 | U35: ='IST Zahlen'!M36 -> 0 | V35: ='PLAN Zahlen'!N38 -> 0 | W35: ='IST Zahlen'!N36 -> 0 | X35: ='PLAN Zahlen'!O38 -> 0 | Y35: ='IST Zahlen'!O36 -> 0 | Z35: ='PLAN Zahlen'!P38 -> 0 | AA35: ='IST Zahlen'!P36 -> 0 | AB35: ='PLAN Zahlen'!Q38 -> 0 | AC35: ='IST Zahlen'!Q36 -> 0 | AD35: ='PLAN Zahlen'!R38 -> -8300 | AE35: ='IST Zahlen'!R36 -> 0 | AF35: ='PLAN Zahlen'!S38 -> -8300 | AG35: ='IST Zahlen'!S36 -> 0
B36: ='PLAN Zahlen'!B39 -> 2.3. | C36: ='PLAN Zahlen'!C39 -> Umsatzsteuer | E36: 0 | F36: ='PLAN Zahlen'!F39 -> -3853 | G36: ='IST Zahlen'!F37 -> 0 | H36: ='PLAN Zahlen'!G39 -> -4151 | I36: ='IST Zahlen'!G37 -> 0 | J36: ='PLAN Zahlen'!H39 -> -5109 | K36: ='IST Zahlen'!H37 -> 0 | L36: ='PLAN Zahlen'!I39 -> -5109 | M36: ='IST Zahlen'!I37 -> 0 | N36: ='PLAN Zahlen'!J39 -> -5109 | O36: ='IST Zahlen'!J37 -> 0 | P36: ='PLAN Zahlen'!K39 -> -5109 | Q36: ='IST Zahlen'!K37 -> 0 | R36: ='PLAN Zahlen'!L39 -> -5109 | S36: ='IST Zahlen'!L37 -> 0 | T36: ='PLAN Zahlen'!M39 -> -5109 | U36: ='IST Zahlen'!M37 -> 0 | V36: ='PLAN Zahlen'!N39 -> -5109 | W36: ='IST Zahlen'!N37 -> 0 | X36: ='PLAN Zahlen'!O39 -> -5109 | Y36: ='IST Zahlen'!O37 -> 0 | Z36: ='PLAN Zahlen'!P39 -> -5109 | AA36: ='IST Zahlen'!P37 -> 0 | AB36: ='PLAN Zahlen'!Q39 -> -5109 | AC36: ='IST Zahlen'!Q37 -> 0 | AD36: ='PLAN Zahlen'!R39 -> -5109 | AE36: ='IST Zahlen'!R37 -> 0 | AF36: ='PLAN Zahlen'!S39 -> -5109 | AG36: ='IST Zahlen'!S37 -> 0
B37: ='PLAN Zahlen'!B40 -> 2.4. | C37: ='PLAN Zahlen'!C40 -> Strom/Gas | E37: 0 | F37: ='PLAN Zahlen'!F40 -> -500 | G37: ='IST Zahlen'!F38 -> 0 | H37: ='PLAN Zahlen'!G40 -> -500 | I37: ='IST Zahlen'!G38 -> 0 | J37: ='PLAN Zahlen'!H40 -> -500 | K37: ='IST Zahlen'!H38 -> 0 | L37: ='PLAN Zahlen'!I40 -> -500 | M37: ='IST Zahlen'!I38 -> 0 | N37: ='PLAN Zahlen'!J40 -> -500 | O37: ='IST Zahlen'!J38 -> 0 | P37: ='PLAN Zahlen'!K40 -> -500 | Q37: ='IST Zahlen'!K38 -> 0 | R37: ='PLAN Zahlen'!L40 -> -500 | S37: ='IST Zahlen'!L38 -> 0 | T37: ='PLAN Zahlen'!M40 -> -500 | U37: ='IST Zahlen'!M38 -> 0 | V37: ='PLAN Zahlen'!N40 -> -500 | W37: ='IST Zahlen'!N38 -> 0 | X37: ='PLAN Zahlen'!O40 -> -500 | Y37: ='IST Zahlen'!O38 -> 0 | Z37: ='PLAN Zahlen'!P40 -> -500 | AA37: ='IST Zahlen'!P38 -> 0 | AB37: ='PLAN Zahlen'!Q40 -> -500 | AC37: ='IST Zahlen'!Q38 -> 0 | AD37: ='PLAN Zahlen'!R40 -> -500 | AE37: ='IST Zahlen'!R38 -> 0 | AF37: ='PLAN Zahlen'!S40 -> -500 | AG37: ='IST Zahlen'!S38 -> 0
B38: ='PLAN Zahlen'!B41 -> 2.5. | C38: ='PLAN Zahlen'!C41 -> Lease/Miete/Tilgung (Fuhrpark) | E38: 0 | F38: ='PLAN Zahlen'!F41 -> -2606.78 | G38: ='IST Zahlen'!F39 -> 0 | H38: ='PLAN Zahlen'!G41 -> -3000 | I38: ='IST Zahlen'!G39 -> 0 | J38: ='PLAN Zahlen'!H41 -> -5000 | K38: ='IST Zahlen'!H39 -> 0 | L38: ='PLAN Zahlen'!I41 -> -5000 | M38: ='IST Zahlen'!I39 -> 0 | N38: ='PLAN Zahlen'!J41 -> -5000 | O38: ='IST Zahlen'!J39 -> 0 | P38: ='PLAN Zahlen'!K41 -> -5000 | Q38: ='IST Zahlen'!K39 -> 0 | R38: ='PLAN Zahlen'!L41 -> -5000 | S38: ='IST Zahlen'!L39 -> 0 | T38: ='PLAN Zahlen'!M41 -> -5000 | U38: ='IST Zahlen'!M39 -> 0 | V38: ='PLAN Zahlen'!N41 -> -5000 | W38: ='IST Zahlen'!N39 -> 0 | X38: ='PLAN Zahlen'!O41 -> -5000 | Y38: ='IST Zahlen'!O39 -> -404.6 | Z38: ='PLAN Zahlen'!P41 -> -5000 | AA38: ='IST Zahlen'!P39 -> -1414 | AB38: ='PLAN Zahlen'!Q41 -> -5000 | AC38: ='IST Zahlen'!Q39 -> -1827 | AD38: ='PLAN Zahlen'!R41 -> -5000 | AE38: ='IST Zahlen'!R39 -> -4096 | AF38: ='PLAN Zahlen'!S41 -> -5000 | AG38: ='IST Zahlen'!S39 -> -7992
B39: ='PLAN Zahlen'!B42 -> 2.5. | C39: ='PLAN Zahlen'!C42 -> Kraftstoff | E39: 0 | F39: ='PLAN Zahlen'!F42 -> -2500 | G39: ='IST Zahlen'!F40 -> 0 | H39: ='PLAN Zahlen'!G42 -> -2500 | I39: ='IST Zahlen'!G40 -> 0 | J39: ='PLAN Zahlen'!H42 -> -3500 | K39: ='IST Zahlen'!H40 -> 0 | L39: ='PLAN Zahlen'!I42 -> -3500 | M39: ='IST Zahlen'!I40 -> 0 | N39: ='PLAN Zahlen'!J42 -> -3500 | O39: ='IST Zahlen'!J40 -> 0 | P39: ='PLAN Zahlen'!K42 -> -3500 | Q39: ='IST Zahlen'!K40 -> 0 | R39: ='PLAN Zahlen'!L42 -> -3500 | S39: ='IST Zahlen'!L40 -> 0 | T39: ='PLAN Zahlen'!M42 -> -3500 | U39: ='IST Zahlen'!M40 -> 0 | V39: ='PLAN Zahlen'!N42 -> -3500 | W39: ='IST Zahlen'!N40 -> 0 | X39: ='PLAN Zahlen'!O42 -> -3500 | Y39: ='IST Zahlen'!O40 -> 0 | Z39: ='PLAN Zahlen'!P42 -> -3500 | AA39: ='IST Zahlen'!P40 -> -2322 | AB39: ='PLAN Zahlen'!Q42 -> -3500 | AC39: ='IST Zahlen'!Q40 -> -4753 | AD39: ='PLAN Zahlen'!R42 -> -3500 | AE39: ='IST Zahlen'!R40 -> -8578 | AF39: ='PLAN Zahlen'!S42 -> -3500 | AG39: ='IST Zahlen'!S40 -> -6573
B40: ='PLAN Zahlen'!B43 -> 2.6. | C40: ='PLAN Zahlen'!C43 -> Miete Geschäftsräume | E40: 0 | F40: ='PLAN Zahlen'!F43 -> -392 | G40: ='IST Zahlen'!F41 -> 0 | H40: ='PLAN Zahlen'!G43 -> -500 | I40: ='IST Zahlen'!G41 -> 0 | J40: ='PLAN Zahlen'!H43 -> -500 | K40: ='IST Zahlen'!H41 -> 0 | L40: ='PLAN Zahlen'!I43 -> -500 | M40: ='IST Zahlen'!I41 -> 0 | N40: ='PLAN Zahlen'!J43 -> -500 | O40: ='IST Zahlen'!J41 -> 0 | P40: ='PLAN Zahlen'!K43 -> -500 | Q40: ='IST Zahlen'!K41 -> 0 | R40: ='PLAN Zahlen'!L43 -> -500 | S40: ='IST Zahlen'!L41 -> 0 | T40: ='PLAN Zahlen'!M43 -> -500 | U40: ='IST Zahlen'!M41 -> 0 | V40: ='PLAN Zahlen'!N43 -> -500 | W40: ='IST Zahlen'!N41 -> 0 | X40: ='PLAN Zahlen'!O43 -> -500 | Y40: ='IST Zahlen'!O41 -> 0 | Z40: ='PLAN Zahlen'!P43 -> -500 | AA40: ='IST Zahlen'!P41 -> 0 | AB40: ='PLAN Zahlen'!Q43 -> -500 | AC40: ='IST Zahlen'!Q41 -> 0 | AD40: ='PLAN Zahlen'!R43 -> -500 | AE40: ='IST Zahlen'!R41 -> 0 | AF40: ='PLAN Zahlen'!S43 -> -500 | AG40: ='IST Zahlen'!S41 -> 0
B41: ='PLAN Zahlen'!B44 -> 2.7. | C41: ='PLAN Zahlen'!C44 -> Rückzahlung Darlehen | E41: 0 | F41: ='PLAN Zahlen'!F44 -> 0 | G41: ='IST Zahlen'!F42 -> 0 | H41: ='PLAN Zahlen'!G44 -> 0 | I41: ='IST Zahlen'!G42 -> 0 | J41: ='PLAN Zahlen'!H44 -> 0 | K41: ='IST Zahlen'!H42 -> 0 | L41: ='PLAN Zahlen'!I44 -> 0 | M41: ='IST Zahlen'!I42 -> 0 | N41: ='PLAN Zahlen'!J44 -> 0 | O41: ='IST Zahlen'!J42 -> 0 | P41: ='PLAN Zahlen'!K44 -> -1000 | Q41: ='IST Zahlen'!K42 -> 0 | R41: ='PLAN Zahlen'!L44 -> -1000 | S41: ='IST Zahlen'!L42 -> 0 | T41: ='PLAN Zahlen'!M44 -> -1000 | U41: ='IST Zahlen'!M42 -> 0 | V41: ='PLAN Zahlen'!N44 -> -1000 | W41: ='IST Zahlen'!N42 -> 0 | X41: ='PLAN Zahlen'!O44 -> -1000 | Y41: ='IST Zahlen'!O42 -> 0 | Z41: ='PLAN Zahlen'!P44 -> -1000 | AA41: ='IST Zahlen'!P42 -> 0 | AB41: ='PLAN Zahlen'!Q44 -> -1000 | AC41: ='IST Zahlen'!Q42 -> 0 | AD41: ='PLAN Zahlen'!R44 -> -1000 | AE41: ='IST Zahlen'!R42 -> 0 | AF41: ='PLAN Zahlen'!S44 -> -1000 | AG41: ='IST Zahlen'!S42 -> 0
B42: ='PLAN Zahlen'!B45 -> 2.8. | C42: ='PLAN Zahlen'!C45 -> Versicherungen | E42: 0 | F42: ='PLAN Zahlen'!F45 -> -1663.6 | G42: ='IST Zahlen'!F43 -> 0 | H42: ='PLAN Zahlen'!G45 -> -2500 | I42: ='IST Zahlen'!G43 -> 0 | J42: ='PLAN Zahlen'!H45 -> -2500 | K42: ='IST Zahlen'!H43 -> 0 | L42: ='PLAN Zahlen'!I45 -> -2500 | M42: ='IST Zahlen'!I43 -> 0 | N42: ='PLAN Zahlen'!J45 -> -2500 | O42: ='IST Zahlen'!J43 -> 0 | P42: ='PLAN Zahlen'!K45 -> -2500 | Q42: ='IST Zahlen'!K43 -> 0 | R42: ='PLAN Zahlen'!L45 -> -2500 | S42: ='IST Zahlen'!L43 -> 0 | T42: ='PLAN Zahlen'!M45 -> -2500 | U42: ='IST Zahlen'!M43 -> - | V42: ='PLAN Zahlen'!N45 -> -2500 | W42: ='IST Zahlen'!N43 -> 0 | X42: ='PLAN Zahlen'!O45 -> -2500 | Y42: ='IST Zahlen'!O43 -> 0 | Z42: ='PLAN Zahlen'!P45 -> -2500 | AA42: ='IST Zahlen'!P43 -> -2611.63 | AB42: ='PLAN Zahlen'!Q45 -> -2500 | AC42: ='IST Zahlen'!Q43 -> -41.65 | AD42: ='PLAN Zahlen'!R45 -> -2500 | AE42: ='IST Zahlen'!R43 -> -83.3 | AF42: ='PLAN Zahlen'!#REF! -> #REF! | AG42: ='IST Zahlen'!S43 -> -2594.2
...
